Workbook
Name averageFX_period: INPUTS!$B$13
Name BS_descr: INPUTS!$B$12
Name CFS_Descr: INPUTS!$B$15
Name comp_period_1: INPUTS!$B$8
Name comp_period_2: INPUTS!$B$9
Name company_name: INPUTS!$B$6
Name currentperiod_end_date: INPUTS!$B$7
Name currentperiod_year: INPUTS!$B$12
Name IFRS_adopt: INPUTS!$B$10
Name IFRS_adoptdate: INPUTS!$B$10
Name IS_Descr: INPUTS!$B$13
Name period: INPUTS!$B$11
Name periodend_spotFX: INPUTS!$B$14
Name priorperiod_end_date: INPUTS!$B$8
Name proforma_date: INPUTS!$B$10
Name SOCE_descr: INPUTS!$B$14

Sheet Dashboard
C1: Current Period | E1: Comparative Period
A3: Balance sheet balancing check | C3: =#REF! -> #REF! | E3: =#REF! -> #REF!
A4: SOCE - Share capital | C4: =#REF! -> #REF! | E4: =#REF! -> #REF!
A5: SOCE - Contributed surplus | C5: =#REF! -> #REF! | E5: =#REF! -> #REF!
A6: SOCE - AOCI | C6: =#REF! -> #REF! | E6: =#REF! -> #REF!
A7: SOCE - Accumulated deficit | C7: =#REF! -> #REF! | E7: =#REF! -> #REF!
A8: SOCE - NCI | C8: =#REF! -> #REF! | E8: =#REF! -> #REF!
A9: SOCE - Total equity | C9: =#REF! -> #REF! | E9: =#REF! -> #REF!

Sheet FS.PRO
A1: =company_name -> Consolidated Hallor Group Inc.
A2: Proforma Financial Statements
A5: Consolidated Working Capital >> | C5: =C20-C37 -> 2036560 | E5: =E20-E37 -> 1645025 | G5: =G20-G37 -> 238317 | I5: =I20-I37 -> 6425422 | K5: =K20-K37 -> 18191186
C7: Consolidated | E7: Consolidated | G7: Consolidated | I7: Consolidated | K7: Hallor Group
C8: 46203 | E8: =EOMONTH(C8,12) -> 46568 | G8: =EOMONTH(E8,12) -> 46934 | I8: =EOMONTH(G8,12) -> 47299 | K8: =EOMONTH(I8,12) -> 47664
A9: =BS_descr -> Statement of Financial Position
C10: =C8 -> 46203 | E10: =E8 -> 46568 | G10: =G8 -> 46934 | I10: =I8 -> 47299 | K10: =K8 -> 47664
A11: ASSETS
A12: Current assets
A13: Cash | B13: $ | C13: =SUMIF(BS.PRO!$AK:$AK,$A13,BS.PRO!L:L) -> 1942431 | D13: $ | E13: =SUMIF(BS.PRO!$AK:$AK,$A13,BS.PRO!R:R) -> 1813362 | F13: $ | G13: =SUMIF(BS.PRO!$AK:$AK,$A13,BS.PRO!X:X) -> 1408703 | H13: $ | I13: =SUMIF(BS.PRO!$AK:$AK,$A13,BS.PRO!AD:AD) -> 9856641 | J13: $ | K13: =SUMIF(BS.PRO!$AK:$AK,$A13,BS.PRO!AJ:AJ) -> 25432405
A14: Receivables | C14: =SUMIF(BS.PRO!$AK:$AK,$A14,BS.PRO!L:L) -> 18 | E14: =SUMIF(BS.PRO!$AK:$AK,$A14,BS.PRO!R:R) -> 18 | G14: =SUMIF(BS.PRO!$AK:$AK,$A14,BS.PRO!X:X) -> 18 | I14: =SUMIF(BS.PRO!$AK:$AK,$A14,BS.PRO!AD:AD) -> 18 | K14: =SUMIF(BS.PRO!$AK:$AK,$A14,BS.PRO!AJ:AJ) -> 18
A15: Prepaid expenses | C15: =SUMIF(BS.PRO!$AK:$AK,$A15,BS.PRO!L:L) -> 0 | E15: =SUMIF(BS.PRO!$AK:$AK,$A15,BS.PRO!R:R) -> 0 | G15: =SUMIF(BS.PRO!$AK:$AK,$A15,BS.PRO!X:X) -> 0 | I15: =SUMIF(BS.PRO!$AK:$AK,$A15,BS.PRO!AD:AD) -> 0 | K15: =SUMIF(BS.PRO!$AK:$AK,$A15,BS.PRO!AJ:AJ) -> 0
A16: Sales tax receivable | C16: =SUMIF(BS.PRO!$AK:$AK,$A16,BS.PRO!L:L) -> 0 | E16: =SUMIF(BS.PRO!$AK:$AK,$A16,BS.PRO!R:R) -> 0 | G16: =SUMIF(BS.PRO!$AK:$AK,$A16,BS.PRO!X:X) -> 0 | I16: =SUMIF(BS.PRO!$AK:$AK,$A16,BS.PRO!AD:AD) -> 0 | K16: =SUMIF(BS.PRO!$AK:$AK,$A16,BS.PRO!AJ:AJ) -> 0
A17: Inventory | C17: =SUMIF(BS.PRO!$AK:$AK,$A17,BS.PRO!L:L) -> 159517 | E17: =SUMIF(BS.PRO!$AK:$AK,$A17,BS.PRO!R:R) -> 602850 | G17: =SUMIF(BS.PRO!$AK:$AK,$A17,BS.PRO!X:X) -> 2142850 | I17: =SUMIF(BS.PRO!$AK:$AK,$A17,BS.PRO!AD:AD) -> 5269517 | K17: =SUMIF(BS.PRO!$AK:$AK,$A17,BS.PRO!AJ:AJ) -> 10309517
A18: Due from related parties | C18: =SUMIF(BS.PRO!$AK:$AK,$A18,BS.PRO!L:L) -> 0 | E18: =SUMIF(BS.PRO!$AK:$AK,$A18,BS.PRO!R:R) -> 0 | G18: =SUMIF(BS.PRO!$AK:$AK,$A18,BS.PRO!X:X) -> 0 | I18: =SUMIF(BS.PRO!$AK:$AK,$A18,BS.PRO!AD:AD) -> 0 | K18: =SUMIF(BS.PRO!$AK:$AK,$A18,BS.PRO!AJ:AJ) -> 0
A19: Current portion of loan receivable | C19: =SUMIF(BS.PRO!$AK:$AK,$A19,BS.PRO!L:L) -> 0 | E19: =SUMIF(BS.PRO!$AK:$AK,$A19,BS.PRO!R:R) -> 0 | G19: =SUMIF(BS.PRO!$AK:$AK,$A19,BS.PRO!X:X) -> 0 | I19: =SUMIF(BS.PRO!$AK:$AK,$A19,BS.PRO!AD:AD) -> 0 | K19: =SUMIF(BS.PRO!$AK:$AK,$A19,BS.PRO!AJ:AJ) -> 0
A20: Total current assets | B20: $ | C20: =SUM(C13:C19) -> 2101966 | D20: $ | E20: =SUM(E13:E19) -> 2416230 | F20: $ | G20: =SUM(G13:G19) -> 3551571 | H20: $ | I20: =SUM(I13:I19) -> 15126176 | J20: $ | K20: =SUM(K13:K19) -> 35741940
A21: Non-current assets
A23: Equipment | C23: =SUMIF(BS.PRO!$AK:$AK,$A23,BS.PRO!L:L) -> 3442 | E23: =SUMIF(BS.PRO!$AK:$AK,$A23,BS.PRO!R:R) -> 3442 | G23: =SUMIF(BS.PRO!$AK:$AK,$A23,BS.PRO!X:X) -> 3442 | I23: =SUMIF(BS.PRO!$AK:$AK,$A23,BS.PRO!AD:AD) -> 3442 | K23: =SUMIF(BS.PRO!$AK:$AK,$A23,BS.PRO!AJ:AJ) -> 3442
A24: Intangible assets | C24: =SUMIF(BS.PRO!$AK:$AK,$A24,BS.PRO!L:L) -> 3015078 | E24: =SUMIF(BS.PRO!$AK:$AK,$A24,BS.PRO!R:R) -> 1758714 | G24: =SUMIF(BS.PRO!$AK:$AK,$A24,BS.PRO!X:X) -> 502350 | I24: =SUMIF(BS.PRO!$AK:$AK,$A24,BS.PRO!AD:AD) -> 314091 | K24: =SUMIF(BS.PRO!$AK:$AK,$A24,BS.PRO!AJ:AJ) -> 314091
A25: Goodwill | C25: =SUMIF(BS.PRO!$AK:$AK,$A25,BS.PRO!L:L) -> 0 | E25: =SUMIF(BS.PRO!$AK:$AK,$A25,BS.PRO!R:R) -> 0 | G25: =SUMIF(BS.PRO!$AK:$AK,$A25,BS.PRO!X:X) -> 0 | I25: =SUMIF(BS.PRO!$AK:$AK,$A25,BS.PRO!AD:AD) -> 0 | K25: =SUMIF(BS.PRO!$AK:$AK,$A25,BS.PRO!AJ:AJ) -> 0
A26: Total non-current assets | B26: $ | C26: =SUM(C23:C25) -> 3018520 | D26: $ | E26: =SUM(E23:E25) -> 1762156 | F26: $ | G26: =SUM(G23:G25) -> 505792 | H26: $ | I26: =SUM(I23:I25) -> 317533 | J26: $ | K26: =SUM(K23:K25) -> 317533
A27: Total Assets | B27: $ | C27: =SUM(C20,C26) -> 5120486 | D27: $ | E27: =SUM(E20,E26) -> 4178386 | F27: $ | G27: =SUM(G20,G26) -> 4057363 | H27: $ | I27: =SUM(I20,I26) -> 15443709 | J27: $ | K27: =SUM(K20,K26) -> 36059473
A28: LIABILITIES
A29: Current liabilities
A30: Accounts payables and accrued liabilities | C30: =-SUMIF(BS.PRO!$AK:$AK,$A30,BS.PRO!L:L) -> 0 | E30: =-SUMIF(BS.PRO!$AK:$AK,$A30,BS.PRO!R:R) -> 0 | G30: =-SUMIF(BS.PRO!$AK:$AK,$A30,BS.PRO!X:X) -> 0 | I30: =-SUMIF(BS.PRO!$AK:$AK,$A30,BS.PRO!AD:AD) -> 0 | K30: =-SUMIF(BS.PRO!$AK:$AK,$A30,BS.PRO!AJ:AJ) -> 0
A31: Accrued Warranty Liability | C31: =-SUMIF(BS.PRO!$AK:$AK,$A31,BS.PRO!L:L) -> 64506 | E31: =-SUMIF(BS.PRO!$AK:$AK,$A31,BS.PRO!R:R) -> 176555 | G31: =-SUMIF(BS.PRO!$AK:$AK,$A31,BS.PRO!X:X) -> 656104 | I31: =-SUMIF(BS.PRO!$AK:$AK,$A31,BS.PRO!AD:AD) -> 1856104 | K31: =-SUMIF(BS.PRO!$AK:$AK,$A31,BS.PRO!AJ:AJ) -> 3956104
A32: Convertible debt | C32: =-SUMIF(BS.PRO!$AK:$AK,$A32,BS.PRO!L:L) -> 0 | E32: =-SUMIF(BS.PRO!$AK:$AK,$A32,BS.PRO!R:R) -> 0 | G32: =-SUMIF(BS.PRO!$AK:$AK,$A32,BS.PRO!X:X) -> 0 | I32: =-SUMIF(BS.PRO!$AK:$AK,$A32,BS.PRO!AD:AD) -> 0 | K32: =-SUMIF(BS.PRO!$AK:$AK,$A32,BS.PRO!AJ:AJ) -> 0
A33: Deferred revenue | C33: =-SUMIF(BS.PRO!$AK:$AK,$A33,BS.PRO!L:L) -> 0 | E33: =-SUMIF(BS.PRO!$AK:$AK,$A33,BS.PRO!R:R) -> 593750 | G33: =-SUMIF(BS.PRO!$AK:$AK,$A33,BS.PRO!X:X) -> 2656250 | I33: =-SUMIF(BS.PRO!$AK:$AK,$A33,BS.PRO!AD:AD) -> 6843750 | K33: =-SUMIF(BS.PRO!$AK:$AK,$A33,BS.PRO!AJ:AJ) -> 13593750
A34: Due to related parties | C34: =-SUMIF(BS.PRO!$AK:$AK,$A34,BS.PRO!L:L) -> 900 | E34: =-SUMIF(BS.PRO!$AK:$AK,$A34,BS.PRO!R:R) -> 900 | G34: =-SUMIF(BS.PRO!$AK:$AK,$A34,BS.PRO!X:X) -> 900 | I34: =-SUMIF(BS.PRO!$AK:$AK,$A34,BS.PRO!AD:AD) -> 900 | K34: =-SUMIF(BS.PRO!$AK:$AK,$A34,BS.PRO!AJ:AJ) -> 900
A35: Income tax payable | C35: =-SUMIF(BS.PRO!$AK:$AK,$A35,BS.PRO!L:L) -> 0 | E35: =-SUMIF(BS.PRO!$AK:$AK,$A35,BS.PRO!R:R) -> 0 | G35: =-SUMIF(BS.PRO!$AK:$AK,$A35,BS.PRO!X:X) -> 0 | I35: =-SUMIF(BS.PRO!$AK:$AK,$A35,BS.PRO!AD:AD) -> 0 | K35: =-SUMIF(BS.PRO!$AK:$AK,$A35,BS.PRO!AJ:AJ) -> 0
A36: Sales tax payable | C36: =-SUMIF(BS.PRO!$AK:$AK,$A36,BS.PRO!L:L) -> 0 | E36: =-SUMIF(BS.PRO!$AK:$AK,$A36,BS.PRO!R:R) -> 0 | G36: =-SUMIF(BS.PRO!$AK:$AK,$A36,BS.PRO!X:X) -> 0 | I36: =-SUMIF(BS.PRO!$AK:$AK,$A36,BS.PRO!AD:AD) -> 0 | K36: =-SUMIF(BS.PRO!$AK:$AK,$A36,BS.PRO!AJ:AJ) -> 0
A37: Total current liabilities | B37: $ | C37: =SUM(C30:C36) -> 65406 | D37: $ | E37: =SUM(E30:E36) -> 771205 | F37: $ | G37: =SUM(G30:G36) -> 3313254 | H37: $ | I37: =SUM(I30:I36) -> 8700754 | J37: $ | K37: =SUM(K30:K36) -> 17550754
A38: Non-current liabilities
A39: Loans and borrowings | C39: =-SUMIF(BS.PRO!$AK:$AK,$A39,BS.PRO!L:L) -> 3000000 | E39: =-SUMIF(BS.PRO!$AK:$AK,$A39,BS.PRO!R:R) -> 3000000 | G39: =-SUMIF(BS.PRO!$AK:$AK,$A39,BS.PRO!X:X) -> 0 | I39: =-SUMIF(BS.PRO!$AK:$AK,$A39,BS.PRO!AD:AD) -> 0 | K39: =-SUMIF(BS.PRO!$AK:$AK,$A39,BS.PRO!AJ:AJ) -> 0
A40: Total Liabilities | B40: $ | C40: =SUM(C37:C39) -> 3065406 | D40: $ | E40: =SUM(E37:E39) -> 3771205 | F40: $ | G40: =SUM(G37:G39) -> 3313254 | H40: $ | I40: =SUM(I37:I39) -> 8700754 | J40: $ | K40: =SUM(K37:K39) -> 17550754
A41: EQUITY
A42: Share capital | B42: $ | C42: =-SUMIF(BS.PRO!$AK:$AK,$A42,BS.PRO!L:L) -> 8555220 | D42: $ | E42: =-SUMIF(BS.PRO!$AK:$AK,$A42,BS.PRO!R:R) -> 8555220 | F42: $ | G42: =-SUMIF(BS.PRO!$AK:$AK,$A42,BS.PRO!X:X) -> 8555220 | H42: $ | I42: =-SUMIF(BS.PRO!$AK:$AK,$A42,BS.PRO!AD:AD) -> 8555220 | J42: $ | K42: =-SUMIF(BS.PRO!$AK:$AK,$A42,BS.PRO!AJ:AJ) -> 8555220
A43: Contributed surplus | C43: =-SUMIF(BS.PRO!$AK:$AK,$A43,BS.PRO!L:L) -> 308750 | E43: =-SUMIF(BS.PRO!$AK:$AK,$A43,BS.PRO!R:R) -> 308750 | G43: =-SUMIF(BS.PRO!$AK:$AK,$A43,BS.PRO!X:X) -> 308750 | I43: =-SUMIF(BS.PRO!$AK:$AK,$A43,BS.PRO!AD:AD) -> 308750 | K43: =-SUMIF(BS.PRO!$AK:$AK,$A43,BS.PRO!AJ:AJ) -> 308750
A44: Accumulated deficit | C44: =-SUMIF(BS.PRO!$AM:$AM,$A44,BS.PRO!L:L) -> -6808890 | E44: =-SUMIF(BS.PRO!$AM:$AM,$A44,BS.PRO!R:R) -> -8456789 | G44: =-SUMIF(BS.PRO!$AM:$AM,$A44,BS.PRO!X:X) -> -8119861 | I44: =-SUMIF(BS.PRO!$AM:$AM,$A44,BS.PRO!AD:AD) -> -2121015 | K44: =-SUMIF(BS.PRO!$AM:$AM,$A44,BS.PRO!AJ:AJ) -> 9644749
...

Sheet FS.1
A1: =company_name -> Consolidated Hallor Group Inc.
A2: Financial Statements
A5: Consolidated Working Capital >> | C5: =C20-C36 -> -683160 | E5: =E20-E36 -> -67788
C7: Consolidated | E7: Hallor Group | T7: META DATA BELOW - DO NOT EDIT
C8: =TEXT(currentperiod_end_date, "MMMM DD, YYYY") -> June 30, 2025 | E8: =TEXT(priorperiod_end_date,"MMMM DD, YYYY") -> June 30, 2024 | T8: =C10 -> June 30, 2025 | U8: =E10 -> June 30, 2024
A9: =BS_descr -> Statement of Financial Position
C10: =C8 -> June 30, 2025 | E10: =E8 -> June 30, 2024 | K10: Change $ | L10: Change % | O10: Movement explanation
A11: ASSETS
A12: Current assets
A13: Cash | B13: $ | C13: =SUMIF('BS.1 - F25'!G:G,FS.1!A13,'BS.1 - F25'!F:F) -> 392 | D13: $ | E13: =SUMIF('BS.2 - F24'!G:G,A13,'BS.2 - F24'!F:F) -> 5604 | K13: =C13-E13 -> -5212 | L13: =IFERROR(K13/E13,0) -> -0.93004996 | O13: Refer to cashflow proof and SCF for movement of cash | T13: 201 | U13: 101
A14: Receivables | C14: =SUMIF('BS.1 - F25'!G:G,FS.1!A14,'BS.1 - F25'!F:F) -> 0 | E14: =SUMIF('BS.2 - F24'!G:G,A14,'BS.2 - F24'!F:F) -> 0 | K14: =C14-E14 -> 0 | L14: =IFERROR(K14/E14,0) -> 0 | O14: Primiarly due to GST rec balance of $26k acquired on acquisition of Hallor Industries; remaining amount due to GST ITCs recognized in Q1 for consolidated group | T14: =IF(C14<>"",MAX(T$13:T13)+1,"") -> 202 | U14: =IF(E14<>"",MAX(U$13:U13)+1,"") -> 102
A15: Prepaid expenses | C15: =SUMIF('BS.1 - F25'!G:G,FS.1!A15,'BS.1 - F25'!F:F) -> 0 | E15: =SUMIF('BS.2 - F24'!G:G,A15,'BS.2 - F24'!F:F) -> 0 | K15: =C15-E15 -> 0 | L15: =IFERROR(K15/E15,0) -> 0 | T15: =IF(C15<>"",MAX(T$13:T14)+1,"") -> 203 | U15: =IF(E15<>"",MAX(U$13:U14)+1,"") -> 103
A16: Sales tax receivable | C16: =SUMIF('BS.1 - F25'!G:G,FS.1!A16,'BS.1 - F25'!F:F) -> 37905 | E16: =SUMIF('BS.2 - F24'!G:G,A16,'BS.2 - F24'!F:F) -> 30450 | K16: =C16-E16 -> 7455 | L16: =IFERROR(K16/E16,0) -> 0.24482759 | T16: =IF(C16<>"",MAX(T$13:T15)+1,"") -> 204 | U16: =IF(E16<>"",MAX(U$13:U15)+1,"") -> 104
A17: Inventory | C17: =SUMIF('BS.1 - F25'!G:G,FS.1!A17,'BS.1 - F25'!F:F) -> 161256 | E17: =SUMIF('BS.2 - F24'!G:G,A17,'BS.2 - F24'!F:F) -> 452364 | K17: =C17-E17 -> -291108 | L17: =IFERROR(K17/E17,1) -> -0.64352601 | O17: From the acquisition of Hallor Industries - was $397,450 on acquisition date; plus additions throughout Q1 | T17: =IF(C17<>"",MAX(T$13:T16)+1,"") -> 205 | U17: =IF(E17<>"",MAX(U$13:U16)+1,"") -> 105
A18: Due from related parties | C18: =SUMIF('BS.1 - F25'!G:G,FS.1!A18,'BS.1 - F25'!F:F) -> 0 | E18: =SUMIF('BS.2 - F24'!G:G,A18,'BS.2 - F24'!F:F) -> 0 | K18: =C18-E18 -> 0 | L18: =IFERROR(K18/E18,0) -> 0 | T18: =IF(C18<>"",MAX(T$13:T17)+1,"") -> 206 | U18: =IF(E18<>"",MAX(U$13:U17)+1,"") -> 106
A19: Current portion of loan receivable | C19: =SUMIF('BS.1 - F25'!G:G,FS.1!A19,'BS.1 - F25'!F:F) -> 0 | E19: =SUMIF('BS.2 - F24'!G:G,A19,'BS.2 - F24'!F:F) -> 0 | K19: =C19-E19 -> 0 | L19: =IFERROR(K19/E19,0) -> 0 | O19: Post-acquisition of Hallor Industries this became an inter-company balance and eliminates on consolidation | T19: =IF(C19<>"",MAX(T$13:T18)+1,"") -> 207 | U19: =IF(E19<>"",MAX(U$13:U18)+1,"") -> 107
A20: Total current assets | B20: $ | C20: =SUM(C13:C19) -> 199553 | D20: $ | E20: =SUM(E13:E19) -> 488418
A21: Non-current assets
A23: Equipment | C23: =SUMIF('BS.1 - F25'!G:G,FS.1!A23,'BS.1 - F25'!F:F) -> 5341 | E23: =SUMIF('BS.2 - F24'!G:G,A23,'BS.2 - F24'!F:F) -> 5341 | K23: =C23-E23 -> 0 | L23: =IFERROR(K23/E23,1) -> 0 | O23: From the acquisition of Hallor Industries - was $6,108 on acquisition date less depreciation | T23: =IF(C23<>"",MAX(T$13:T22)+1,"") -> 208 | U23: =IF(E23<>"",MAX(U$13:U22)+1,"") -> 108
A24: Intangible assets | C24: =SUMIF('BS.1 - F25'!G:G,FS.1!A24,'BS.1 - F25'!F:F) -> 4271442 | E24: =SUMIF('BS.2 - F24'!G:G,A24,'BS.2 - F24'!F:F) -> 5527806 | K24: =C24-E24 -> -1256364 | L24: =IFERROR(K24/E24,1) -> -0.22728077 | O24: From the acquisition of Hallor Industries | T24: =IF(C24<>"",MAX(T$13:T23)+1,"") -> 209 | U24: =IF(E24<>"",MAX(U$13:U23)+1,"") -> 109
A25: Goodwill | C25: =SUMIF('BS.1 - F25'!G:G,FS.1!A25,'BS.1 - F25'!F:F) -> 0 | E25: =SUMIF('BS.2 - F24'!G:G,A25,'BS.2 - F24'!F:F) -> 0 | K25: =C25-E25 -> 0
A26: Total non-current assets | B26: $ | C26: =SUM(C23:C25) -> 4276783 | D26: $ | E26: =SUM(E23:E25) -> 5533147
A27: Total Assets | B27: $ | C27: =SUM(C20,C26) -> 4476336 | D27: $ | E27: =SUM(E20,E26) -> 6021565
A28: LIABILITIES
A29: Current liabilities
A30: Accounts payables and accrued liabilities | C30: =-SUMIF('BS.1 - F25'!G:G,FS.1!A30,'BS.1 - F25'!F:F) -> 603276 | E30: =-SUMIF('BS.2 - F24'!G:G,A30,'BS.2 - F24'!F:F) -> 349791 | K30: =C30-E30 -> 253485 | L30: =IFERROR(K30/E30,1) -> 0.72467559 | O30: Opening bal of $67k from YE: Net accrual increase: $44k for accrued legal (McMillian) and accounitng expenses (MNP) in Hallor Group; Add; $178k of AP assumed on acquisition of Hallor Industries; Net increase in AP of $62k in Hallor Group YTD 6 mths Net decrease in AP of $14k in Hallor industries YTD 6 mths | T30: =IF(C30<>"",MAX(T$13:T29)+1,"") -> 210 | U30: =IF(E30<>"",MAX(U$13:U29)+1,"") -> 110
A31: Warranty liability | C31: =-SUMIF('BS.1 - F25'!G:G,FS.1!A31,'BS.1 - F25'!F:F) -> 0 | E31: =-SUMIF('BS.2 - F24'!G:G,A31,'BS.2 - F24'!F:F) -> 0 | K31: =C31-E31 -> 0 | L31: =IFERROR(K31/E31,0) -> 0 | T31: =IF(C31<>"",MAX(T$13:T30)+1,"") -> 211 | U31: =IF(E31<>"",MAX(U$13:U30)+1,"") -> 111
A32: Convertible debt | C32: =-SUMIF('BS.1 - F25'!G:G,FS.1!A32,'BS.1 - F25'!F:F) -> 274099 | E32: =-SUMIF('BS.2 - F24'!G:G,A32,'BS.2 - F24'!F:F) -> 204577 | K32: =C32-E32 -> 69522 | L32: =IFERROR(K32/E32,1) -> 0.33983292 | O32: $225k of convertible note subscription occurred in Q1; the conversion feature recognized as derivative liability, FV'd first and residual of face-value on note allocated to host debt liability ($150,000). Convertiblenote balance is accreted up and includes interest payable amount. See Tab COV.DEBT for more details | T32: =IF(C32<>"",MAX(T$13:T31)+1,"") -> 212 | U32: =IF(E32<>"",MAX(U$13:U31)+1,"") -> 112
A33: Derivative liability | C33: =-SUMIF('BS.1 - F25'!G:G,FS.1!A33,'BS.1 - F25'!F:F) -> 0 | E33: =-SUMIF('BS.2 - F24'!G:G,A33,'BS.2 - F24'!F:F) -> 0 | K33: =C33-E33 -> 0 | L33: =IFERROR(K33/E33,1) -> 1 | O33: $225k of convertible note subscription occurred in Q1; the conversion feature recognized as derivative liability, FV'd first and residual of face-value on note allocated to host debt liability. Refer to Tab DER.V in this workbook for valuation of derivative. | T33: =IF(C33<>"",MAX(T$13:T32)+1,"") -> 213 | U33: =IF(E33<>"",MAX(U$13:U32)+1,"") -> 113
A34: Income tax payable | C34: =-SUMIF('BS.1 - F25'!G:G,FS.1!A34,'BS.1 - F25'!F:F) -> 0 | E34: =-SUMIF('BS.2 - F24'!G:G,A34,'BS.2 - F24'!F:F) -> 0 | K34: =C34-E34 -> 0 | L34: =IFERROR(K34/E34,0) -> 0 | T34: =IF(C34<>"",MAX(T$13:T33)+1,"") -> 214 | U34: =IF(E34<>"",MAX(U$13:U33)+1,"") -> 114
A35: Due to related parties | C35: =-SUMIF('BS.1 - F25'!G:G,FS.1!A35,'BS.1 - F25'!F:F) -> 5338 | E35: =-SUMIF('BS.2 - F24'!G:G,A35,'BS.2 - F24'!F:F) -> 1838 | K35: =C35-E35 -> 3500 | L35: =IFERROR(K35/E35,0) -> 1.9042437 | T35: =IF(C35<>"",MAX(T$13:T34)+1,"") -> 215 | U35: =IF(E35<>"",MAX(U$13:U34)+1,"") -> 115
A36: Total current liabilities | B36: $ | C36: =SUM(C30:C35) -> 882713 | D36: $ | E36: =SUM(E30:E35) -> 556206
A37: Non-current liabilities
A38: Loans and borrowings | C38: =-SUMIF('BS.1 - F25'!G:G,FS.1!A38,'BS.1 - F25'!F:F) -> 0 | E38: =-SUMIF('BS.2 - F24'!G:G,A38,'BS.2 - F24'!F:F) -> 0 | K38: =C38-E38 -> 0 | L38: =IFERROR(K38/E38,0) -> 0
A39: Total Liabilities | B39: $ | C39: =SUM(C36:C38) -> 882713 | D39: $ | E39: =SUM(E36:E38) -> 556206
A40: EQUITY
A41: Share capital | B41: $ | C41: =-SUMIF('BS.1 - F25'!G:G,FS.1!A41,'BS.1 - F25'!F:F) -> 8224099 | D41: $ | E41: =-SUMIF('BS.2 - F24'!G:G,A41,'BS.2 - F24'!F:F) -> 8224099 | K41: =C41-E41 -> 0 | L41: =IFERROR(K41/E41,0) -> 0 | O41: $6M share consideration to acquire Hallor Industries; $450k finders fee on closing of acquisition | T41: =IF(C41<>"",MAX(T$13:T40)+1,"") -> 216 | U41: =IF(E41<>"",MAX(U$13:U40)+1,"") -> 116
A42: Contributed surplus | C42: =-SUMIF('BS.1 - F25'!G:G,FS.1!A42,'BS.1 - F25'!F:F) -> 308750 | E42: =-SUMIF('BS.2 - F24'!G:G,A42,'BS.2 - F24'!F:F) -> 308750 | K42: =C42-E42 -> 0 | L42: =IFERROR(K42/E42,0) -> 0 | T42: =IF(C42<>"",MAX(T$13:T41)+1,"") -> 217 | U42: =IF(E42<>"",MAX(U$13:U41)+1,"") -> 117
A43: Accumulated deficit | C43: =-SUMIF('BS.1 - F25'!I:I,FS.1!A43,'BS.1 - F25'!F:F) -> -4939226 | E43: =-SUMIF('BS.2 - F24'!I:I,FS.1!A43,'BS.2 - F24'!F:F) -> #REF! | K43: =C43-E43 -> #REF! | L43: =IFERROR(K43/E43,0) -> 0 | O43: Net loss in the period - see P&L variance analysis for details | T43: =IF(C43<>"",MAX(T$13:T42)+1,"") -> 218 | U43: =IF(E43<>"",MAX(U$13:U42)+1,"") -> #REF!
A44: Total Shareholders’ (deficit) equity | B44: $ | C44: =SUM(C41:C43) -> 3593623 | D44: $ | E44: =SUM(E41:E43) -> #REF!
...

Sheet Note Disclosures
A1: =company_name -> Consolidated Hallor Group Inc.
A2: Note Disclosures
A4: SELECT Current Reporting Period >> | B4: =INPUTS!B3 -> Q4
A6: EXPAND BELOW - UNUSED NOTES
A8: Segment Reporting - NOT USED
C9: =currentperiod_end_date -> 45838 | D9: =priorperiod_end_date -> 45473
A10: Canada
A11: USA
A12: Europe
A13: Asia
A14: Total revenue | C14: =SUM(C10:C12) -> 0 | D14: =SUM(D10:D12) -> 0
A16: Check | C16: =C14-#REF! -> #REF! | D16: =D14-#REF! -> #REF!
C18: =currentperiod_end_date -> 45838 | D18: =priorperiod_end_date -> 45473
A19: Canada
A21: Total non-current assets | C21: =SUM(C19:C20) -> 0 | D21: =SUM(D19:D20) -> 0
A23: Check | C23: =C21-#REF! -> #REF! | D23: =D21-#REF! -> #REF!
A25: Trade and other receivables - NOT USED
C26: =currentperiod_end_date -> 45838 | D26: =priorperiod_end_date -> 45473
A27: Trade receivables from contracts with customers | C27: =SUMIF('FY Current'!I:I,'Note Disclosures'!$A27,'FY Current'!G:G) -> 0 | D27: =SUMIF(#REF!,$A27,#REF!) -> #REF!
A28: Sales taxes receivable | C28: =SUMIF('FY Current'!I:I,'Note Disclosures'!$A28,'FY Current'!G:G) -> 0 | D28: =SUMIF(#REF!,$A28,#REF!) -> #REF!
A29: Other receivables | C29: =SUMIF('FY Current'!I:I,'Note Disclosures'!$A29,'FY Current'!G:G) -> 0 | D29: =SUMIF(#REF!,$A29,#REF!) -> #REF!
A30: Loss allowance | C30: =SUMIF('FY Current'!I:I,'Note Disclosures'!$A30,'FY Current'!G:G) -> 0 | D30: =SUMIF(#REF!,$A30,#REF!) -> #REF!
A31: Total trade and other receivables | C31: =SUM(C27:C30) -> 0 | D31: =SUM(D27:D30) -> #REF!
A33: Check | C33: =C31-#REF! -> #REF! | D33: =D31-#REF! -> #REF!
A35: Prepaid expenses and deposits - NOT USED
C36: =currentperiod_end_date -> 45838 | D36: =priorperiod_end_date -> 45473
A37: Prepaid listing expenses | C37: =SUMIF('FY Current'!I:I,'Note Disclosures'!$A37,'FY Current'!G:G) -> 0 | D37: =SUMIF(#REF!,$A37,#REF!) -> #REF!
A38: Other prepaid expenses | C38: =SUMIF('FY Current'!I:I,'Note Disclosures'!$A38,'FY Current'!G:G) -> 0 | D38: =SUMIF(#REF!,$A38,#REF!) -> #REF!
A39: Deposit | C39: =SUMIF('FY Current'!I:I,'Note Disclosures'!$A39,'FY Current'!G:G) -> 0 | D39: =SUMIF(#REF!,$A39,#REF!) -> #REF!
A40: Total prepaid expenses and deposits | C40: =SUM(C37:C39) -> 0 | D40: =SUM(D37:D39) -> #REF!
A41: Current portion of prepaid expenses and deposits | C41: 204945 | D41: 5644
A42: Non-current portion of prepaid expenses and deposits | C42: =C40-C41 -> -204945 | D42: =D40-D41 -> #REF!
A44: Check | C44: =C41-#REF! -> #REF! | D44: =D41-#REF! -> #REF!
A45: Check | C45: =C42-#REF! -> #REF! | D45: =D42-#REF! -> #REF!
A47: Property and equipment- NOT USED
C48: Computer Equipment | D48: Furniture and Equipment | E48: Leasehold improvements | F48: Open | G48: Total
A49: Cost
A50: =IFRS_adopt -> 45930 | F50: 0 | G50: =SUM(C50:F50) -> 0
A51: Additions | F51: 0 | G51: =SUM(C51:F51) -> 0
A52: =comp_period_1 -> 45473 | C52: =SUM(C50:C51) -> 0 | D52: =SUM(D50:D51) -> 0 | E52: =SUM(E50:E51) -> 0 | F52: =SUM(F50:F51) -> 0 | G52: =SUM(C52:F52) -> 0
...

Sheet Cash Flow Proof
A1: =company_name -> Consolidated Hallor Group Inc.
A2: Cash Flow Proof
D4: AJEs | E4: [Placeholder] | F4: Reclass | G4: Total
A5: =priorperiod_end_date -> 45473 | B5: =_xlfn.XLOOKUP(A5,#REF!,#REF!,0,0,1) -> #REF! | C5: =_xlfn.XLOOKUP(A5,#REF!,#REF!,0,0,1) -> #REF! | D5: 0 | G5: =SUM(B5:F5) -> #REF!
A6: =currentperiod_end_date -> 45838 | B6: =_xlfn.XLOOKUP(A6,#REF!,#REF!,0,0,1) -> #REF! | C6: =_xlfn.XLOOKUP(A6,#REF!,#REF!,0,0,1) -> #REF! | D6: 0 | G6: =SUM(B6:F6) -> #REF!
A7: Net Change | B7: =B6-B5 -> #REF! | C7: =C6-C5 -> #REF! | D7: =D6-D5 -> 0 | E7: =E6-E5 -> 0 | F7: =F6-F5 -> 0 | G7: =G6-G5 -> #REF!
A9: Operating activities
A10: Net loss for the period | B10: =_xlfn.XLOOKUP(A10,#REF!,#REF!,0,0,1) -> #REF! | C10: =_xlfn.XLOOKUP(A10,#REF!,#REF!,0,0,1) -> #REF! | D10: =-122911-92253 -> -215164 | G10: =ROUND(SUM(B10:F10),0) -> #REF! | J10: =#REF! -> #REF! | K10: =J10-G10 -> #REF!
A12: Items not affecting cash:
A13: Depreciation and amortization | B13: =_xlfn.XLOOKUP(A13,#REF!,#REF!,0,0,1) -> #REF! | C13: =_xlfn.XLOOKUP(A13,#REF!,#REF!,0,0,1) -> #REF! | D13: ='FY Current'!#REF! -> #REF! | G13: =ROUND(SUM(B13:F13),0) -> #REF!
A14: Bad debt | B14: =_xlfn.XLOOKUP(A14,#REF!,#REF!,0,0,1) -> #REF! | C14: =_xlfn.XLOOKUP(A14,#REF!,#REF!,0,0,1) -> #REF! | G14: =ROUND(SUM(B14:F14),0) -> #REF!
A15: Gain from debt forgiveness | B15: =_xlfn.XLOOKUP(A15,#REF!,#REF!,0,0,1) -> #REF! | C15: =_xlfn.XLOOKUP(A15,#REF!,#REF!,0,0,1) -> #REF! | G15: =ROUND(SUM(B15:F15),0) -> #REF!
A16: Net financing cost | B16: =_xlfn.XLOOKUP(A16,#REF!,#REF!,0,0,1) -> #REF! | C16: =_xlfn.XLOOKUP(A16,#REF!,#REF!,0,0,1) -> #REF! | D16: -4643 | G16: =ROUND(SUM(B16:F16),0) -> #REF!
A17: Share-based payments | B17: =_xlfn.XLOOKUP(A17,#REF!,#REF!,0,0,1) -> #REF! | C17: =_xlfn.XLOOKUP(A17,#REF!,#REF!,0,0,1) -> #REF! | G17: =SUM(B17:F17) -> #REF!
A18: Foreign currency exchange | B18: =_xlfn.XLOOKUP(A18,#REF!,#REF!,0,0,1) -> #REF! | C18: =_xlfn.XLOOKUP(A18,#REF!,#REF!,0,0,1) -> #REF! | G18: =ROUND(SUM(B18:F18),0) -> #REF!
A19: Current tax recovery (expense) | B19: =_xlfn.XLOOKUP(A19,#REF!,#REF!,0,0,1) -> #REF! | C19: =_xlfn.XLOOKUP(A19,#REF!,#REF!,0,0,1) -> #REF! | G19: =ROUND(SUM(B19:F19),0) -> #REF!
A20: Deferred tax recovery (expense) | B20: =_xlfn.XLOOKUP(A20,#REF!,#REF!,0,0,1) -> #REF! | C20: =_xlfn.XLOOKUP(A20,#REF!,#REF!,0,0,1) -> #REF! | G20: =ROUND(SUM(B20:F20),0) -> #REF!
A22: Net change in non-cash working capital items:
A23: Bank indebtedness | B23: =_xlfn.XLOOKUP(A23,#REF!,#REF!,0,0,1) -> #REF! | C23: =_xlfn.XLOOKUP(A23,#REF!,#REF!,0,0,1) -> #REF! | G23: =SUM(B23:F23) -> #REF!
A24: Trade and other receivables | B24: =_xlfn.XLOOKUP(A24,#REF!,#REF!,0,0,1) -> #REF! | C24: =_xlfn.XLOOKUP(A24,#REF!,#REF!,0,0,1) -> #REF! | G24: =ROUND(SUM(B24:F24),0) -> #REF!
A25: Deferred tax asset | B25: =_xlfn.XLOOKUP(A25,#REF!,#REF!,0,0,1) -> #REF! | C25: =_xlfn.XLOOKUP(A25,#REF!,#REF!,0,0,1) -> #REF! | G25: =ROUND(SUM(B25:F25),0) -> #REF!
A26: Prepaid expenses and deposits | B26: =_xlfn.XLOOKUP(A26,#REF!,#REF!,0,0,1) -> #REF! | C26: =_xlfn.XLOOKUP(A26,#REF!,#REF!,0,0,1) -> #REF! | G26: =ROUND(SUM(B26:F26),0) -> #REF!
A27: Trade payables and accrued liabilities | B27: =_xlfn.XLOOKUP(A27,#REF!,#REF!,0,0,1) -> #REF! | C27: =_xlfn.XLOOKUP(A27,#REF!,#REF!,0,0,1) -> #REF! | D27: =-D10-D13+1-D47-D16 -> #REF! | G27: =ROUND(SUM(B27:F27),0) -> #REF! | J27: =#REF! -> #REF!
A28: Due to/from related parties | B28: =_xlfn.XLOOKUP(A28,#REF!,#REF!,0,0,1) -> #REF! | C28: =_xlfn.XLOOKUP(A28,#REF!,#REF!,0,0,1) -> #REF! | G28: =ROUND(SUM(B28:F28),0) -> #REF! | I28: =G28/averageFX_period -> #REF!
A29: Taxes paid | B29: =_xlfn.XLOOKUP(A29,#REF!,#REF!,0,0,1) -> #REF! | C29: =_xlfn.XLOOKUP(A29,#REF!,#REF!,0,0,1) -> #REF! | G29: =ROUND(SUM(B29:F29),0) -> #REF!
A30: Cash used in operating activities: | G30: =SUM(G10:G29) -> #REF!
A32: Investing activities
A33: Acquisition of property and equipment | B33: =_xlfn.XLOOKUP(A33,#REF!,#REF!,0,0,1) -> #REF! | C33: =_xlfn.XLOOKUP(A33,#REF!,#REF!,0,0,1) -> #REF! | G33: =ROUND(SUM(B33:F33),0) -> #REF!
A34: Expenditures on intangible assets | B34: =_xlfn.XLOOKUP(A34,#REF!,#REF!,0,0,1) -> #REF! | C34: =_xlfn.XLOOKUP(A34,#REF!,#REF!,0,0,1) -> #REF! | G34: =ROUND(SUM(B34:F34),0) -> #REF!
A35: Interest received | B35: =_xlfn.XLOOKUP(A35,#REF!,#REF!,0,0,1) -> #REF! | C35: =_xlfn.XLOOKUP(A35,#REF!,#REF!,0,0,1) -> #REF! | G35: =ROUND(SUM(B35:F35),0) -> #REF!
A37: Net cash flows from investing activities | G37: =SUM(G33:G36) -> #REF!
A39: Financing activities
A40: Repayment of lease liabilities | B40: =_xlfn.XLOOKUP(A40,#REF!,#REF!,0,0,1) -> #REF! | C40: =_xlfn.XLOOKUP(A40,#REF!,#REF!,0,0,1) -> #REF! | G40: =ROUND(SUM(B40:F40),0) -> #REF!
A41: Repayment of loans and borrowings | B41: =_xlfn.XLOOKUP(A41,#REF!,#REF!,0,0,1) -> #REF! | C41: =_xlfn.XLOOKUP(A41,#REF!,#REF!,0,0,1) -> #REF! | G41: =ROUND(SUM(B41:F41),0) -> #REF!
A42: Interest paid | B42: =_xlfn.XLOOKUP(A42,#REF!,#REF!,0,0,1) -> #REF! | C42: =_xlfn.XLOOKUP(A42,#REF!,#REF!,0,0,1) -> #REF! | G42: =ROUND(SUM(B42:F42),0) -> #REF!
A43: Proceeds from loans, net of transaction costs | B43: =_xlfn.XLOOKUP(A43,#REF!,#REF!,0,0,1) -> #REF! | C43: =_xlfn.XLOOKUP(A43,#REF!,#REF!,0,0,1) -> #REF! | G43: =ROUND(SUM(B43:F43),0) -> #REF!
A44: Increase (decrease) of bank indebtedness | B44: =_xlfn.XLOOKUP(A44,#REF!,#REF!,0,0,1) -> #REF! | C44: =_xlfn.XLOOKUP(A44,#REF!,#REF!,0,0,1) -> #REF! | G44: =ROUND(SUM(B44:F44),0) -> #REF!
A45: Proceeds from private placements | B45: =_xlfn.XLOOKUP(A45,#REF!,#REF!,0,0,1) -> #REF! | C45: =_xlfn.XLOOKUP(A45,#REF!,#REF!,0,0,1) -> #REF! | G45: =ROUND(SUM(B45:F45),0) -> #REF!
A46: Share issue costs | B46: =_xlfn.XLOOKUP(A46,#REF!,#REF!,0,0,1) -> #REF! | C46: =_xlfn.XLOOKUP(A46,#REF!,#REF!,0,0,1) -> #REF! | G46: =ROUND(SUM(B46:F46),0) -> #REF!
A47: (Repayment of) advances from related party | B47: =_xlfn.XLOOKUP(A47,#REF!,#REF!,0,0,1) -> #REF! | C47: =_xlfn.XLOOKUP(A47,#REF!,#REF!,0,0,1) -> #REF! | D47: =-539223 -> -539223 | G47: =ROUND(SUM(B47:F47),0) -> #REF! | J47: =#REF! -> #REF! | L47: =G47-J47 -> #REF!
...

Sheet WASO - 2022
D2: Weighted Average Shares Outstanding Calculations
F3: for the year ending | H3: =EDATE(J4,12) -> 44926
G4: (previous year end | J4: 44561
G6: 12 Months | H6: 3 months | K6: 9 months | L6: 3 months | O6: 6 months | P6: 3 months | S6: 3 months
F7: 12 mos. | G7: =H7 -> 44926 | H7: =H3 -> 44926 | J7: 9 mos. | K7: =L7 -> 44834 | L7: =EDATE(J4,9) -> 44834 | N7: 6 mos. | O7: =P7 -> 44742 | P7: =EDATE(J4,6) -> 44742 | R7: 3 mos. | S7: =EDATE(J4,3) -> 44651
F8: days | G8: WTD. AVG. | H8: WTD. AVG. | J8: days | K8: WTD. AVG. | L8: WTD. AVG. | N8: days | O8: WTD. AVG. | P8: WTD. AVG. | R8: days | S8: WTD. AVG.
D9: # Shares | G9: =G7-J4 -> 365 | H9: =H7-L7 -> 92 | K9: =K7-J4 -> 273 | L9: =L7-P7 -> 92 | O9: =O7-J4 -> 181 | P9: =P7-S7 -> 91 | S9: =S7-J4 -> 90
B10: =J4+1 -> 44562 | C10: OPENING BALANCE | D10: 26000000
F11: =IF(D11>0,G$7-B11+1," ") | G11: =IF(D11>0,F11/G$9*$D11," ") | J11: =IF(D11>0,K$7-B11+1," ") | K11: =IF(D11>0,J11/K$9*$D11," ") | N11: =IF(D11>0,O$7-B11+1," ") | O11: =IF(D11>0,N11/O$9*$D11," ") | R11: =IF(D11>0,S$7-B11+1," ") | S11: =IF(D11>0,R11/S$9*$D11," ")
F12: =IF(D12>0,G$7-B12+1," ") | G12: =IF(D12>0,F12/G$9*$D12," ") | J12: =IF(D12>0,K$7-B12+1," ") | K12: =IF(D12>0,J12/K$9*$D12," ") | N12: =IF(D12>0,O$7-B12+1," ") | O12: =IF(D12>0,N12/O$9*$D12," ") | R12: =IF(D12>0,S$7-B12+1," ") | S12: =IF(D12>0,R12/S$9*D12," ")
F13: =IF(D13>0,G$7-B13+1," ") | G13: =IF(D13>0,F13/G$9*$D13," ") | J13: =IF(D13>0,K$7-B13+1," ") | K13: =IF(D13>0,J13/K$9*$D13," ") | N13: =IF(D13>0,O$7-B13+1," ") | O13: =IF(D13>0,N13/O$9*$D13," ") | R13: =IF(D13>0,S$7-B13+1," ") | S13: =IF(D13>0,R13/S$9*D13," ")
F14: =IF(D14>0,G$7-B14+1," ") | G14: =IF(D14>0,F14/G$9*$D14," ") | J14: =IF(D14>0,K$7-B14+1," ") | K14: =IF(D14>0,J14/K$9*$D14," ") | N14: =IF(D14>0,O$7-B14+1," ") | O14: =IF(D14>0,N14/O$9*$D14," ") | R14: =IF(D14>0,S$7-B14+1," ") | S14: =IF(D14>0,R14/S$9*$D14," ")
C15: WEIGHTED AVG. SHARES O/S FOR 3 MO.S | S15: =SUM(S10:S14)+D10 -> 26000000
B17: =EDATE(B10,3) -> 44652 | C17: OPENING BALANCE | D17: =SUM(D10:D14) -> 26000000
G19: =IF(D19>0,F19/G$9*$D19," ") | J19: =IF(D19>0,K$7-B19+1," ") | K19: =IF(D19>0,J19/K$9*$D19," ") | N19: =IF(D19>0,O$7-B19+1," ") | O19: =IF(D19>0,N19/O$9*$D19," ") | P19: =IF(D19>0,N19/P$9*D19," ")
F20: =IF(D20>0,G$7-B20+1," ") | G20: =IF(D20>0,F20/G$9*$D20," ") | J20: =IF(D20>0,K$7-B20+1," ") | K20: =IF(D20>0,J20/K$9*$D20," ") | N20: =IF(D20>0,O$7-B20+1," ") | O20: =IF(D20>0,N20/O$9*$D20," ") | P20: =IF(D20>0,N20/P$9*D20," ")
C22: WEIGHTED AVG. SHARES O/S FOR 6 MO.S | O22: =SUM(O10:O21)+D10 -> 26000000
C23: WEIGHTED AVG. SHARES O/S FOR 3 MO.S | P23: =SUM(P18:P21)+D17 -> 26000000
B25: =EDATE(B17,3) -> 44743 | C25: OPENING BALANCE | D25: =SUM(D17:D21) -> 26000000
K26: =IF(D26>0,J26/K$9*$D26," ") | L26: =IF(D26>0,J26/L$9*D26," ")
F27: =IF(D27>0,G$7-B27+1," ") | G27: =IF(D27>0,F27/G$9*$D27," ") | J27: =IF(D27>0,K$7-B27+1," ") | K27: =IF(D27>0,J27/K$9*$D27," ") | L27: =IF(D27>0,J27/L$9*D27," ")
F28: =IF(D28>0,G$7-B28+1," ") | G28: =IF(D28>0,F28/G$9*$D28," ") | J28: =IF(D28>0,K$7-B28+1," ") | K28: =IF(D28>0,J28/K$9*$D28," ") | L28: =IF(D28>0,J28/L$9*D28," ") | N28: =IF(D28>0,O$7-B28+1," ")
C29: WEIGHTED AVG. SHARES O/S FOR 9 MO.S | K29: =SUM(K10:K28)+D10 -> 26000000
C30: WEIGHTED AVG. SHARES O/S FOR 3 MO.S | L30: =SUM(L24:L28)+D25 -> 26000000
B31: =EDATE(B25,3) -> 44835 | C31: OPENING BALANCE | D31: =SUM(D25:D28) -> 26000000
F33: =IF(D33>0,G$7-B33+1," ") | G33: =IF(D33>0,F33/365*$D33," ") | H33: =IF(D33>0,F33/H$9*D33," ")
F34: =IF(D34>0,G$7-#REF!+1," ") | G34: =IF(D34>0,F34/365*$D34," ") | H34: =IF(D34>0,F34/H$9*D34," ") | J34: =IF(D34>0,K$7-#REF!+1," ")
C35: WEIGHTED AVG. SHARES O/S FOR 12 MO.S | G35: =SUM(G10:G34)+D10 -> 26000000
C36: WEIGHTED AVG. SHARES O/S FOR 3 MO.S | H36: =SUM(H32:H34)+D31 -> 26000000
B38: =B31+91 -> 44926 | C38: CLOSING BALANCE | D38: =SUM(D31:D34) -> 26000000
D41: =#REF! -> #REF! | E41: =#REF! -> #REF! | G41: =#REF! -> #REF! | H41: =#REF! -> #REF!
D42: =E42 -> 45473 | E42: =EOMONTH(EDATE(G42,-12),0) -> 45473 | G42: =currentperiod_end_date -> 45838 | H42: =currentperiod_end_date -> 45838
C43: Ending WASO | D43: 14478261 | E43: 6887671.2 | G43: =H36 -> 26000000 | H43: =G35 -> 26000000
C45: Total Loss | E45: =#REF! -> #REF! | H45: =#REF! -> #REF!
C46: Basic and diluted loss per share | D46: =IFERROR(D45/D43,0) -> 0 | E46: =IFERROR(E45/E43,0) -> 0 | G46: =IFERROR(G45/G43,0) -> 0 | H46: =IFERROR(H45/H43,0) -> 0

Sheet Prospectus Table
A1: WITH FINANCING REFLECTED
A2: Sources of Available Funds | B2: Available Funds ($)
A3: Working capital of Company | B3: 288310 | H3: as at November 30, 2023
A4: Committed convertible debenture financing per Convertible Note | B4: =500000 -> 500000
A5: Committed production financing ($CAD) | B5: =2500000*I5 -> 3400000 | H5: USD to CAD FX rate | I5: 1.36
A6: Total pro forma working capital (unaudited) | B6: =SUM(B3:B5) -> 4188310
A9: Principal Purposes | B9: Funds ($)
A10: Total working capital available | B10: =B6 -> 4188310
A11: Less: Estimated product commercialization | B11: =-50000-2800000-50000 -> -2900000
A12: Less: Advertising and marketing | B12: =-60000 -> -60000
A13: Less: Estimated test-trial expenses | B13: -18000
A14: Less: Estimated expenses related to the development of additional modular components | B14: =-20000+5500 -> -14500
A15: Less: Estimated salaries | B15: =-372000 -> -372000
A16: Less: Estimated transaction fees (legal, accounting, listing fee, etc.) | B16: =-100000+55000 -> -45000
A17: Total use of proceeds | B17: =SUM(B11:B16) -> -3409500
A18: Unallocated funds (unaudited) | B18: =SUM(B10,B17) -> 778810 | C18: << must be positive $100k
A21: WITHOUT FINANCING REFLECTED | H21: [A] | I21: proforma exclude | J21: [A] | K21: [A] | L21: [A] | M21: [A] | N21: [A] | O21: proforma exclude
A22: Sources of Available Funds | B22: Available Funds ($) | D22: Proforma WC of Company | F22: Accounting WC | H22: Cash | I22: Ashik funds | J22: GST Rec | K22: Inventory | L22: Oth Asset | M22: Accounts Payable | N22: Due to RPT | O22: Conv Debt
A23: Working capital of Company | B23: =FS.1!C5+FS.1!C32+FS.1!C33 -> -409061 | D23: =SUM(H23,J23:N23) -> -446966 | E23: [A] | F23: =SUM(H23:O23) -> -721065 | H23: =H26 -> 392 | I23: 0 | J23: =J26 -> 0 | K23: =K26 -> 161256 | L23: 0 | M23: =M26 -> -603276 | N23: =N26 -> -5338 | O23: =O26 -> -274099
A24: Committed convertible debenture financing per Convertible Note | B24: =B4 -> 500000
A25: Committed production financing ($CAD) | B25: 0 | C25: NOV 2023 | D25: =SUM(H25,J25:N25) -> 288310 | E25: [A] | F25: =SUM(H25,J25:O25) -> 734 | H25: 44447 | I25: 500000 | J25: 49282 | K25: 427134 | L25: 0 | M25: -231653 | N25: -900 | O25: -287576 | P25: << NOV numbers as previously calc'd and communicated to Habib via email
A26: Total pro forma working capital (unaudited) | B26: =SUM(B23:B25) -> 90939 | C26: DEC 2023 | D26: =SUM(H26,J26:N26) -> -446966 | E26: [A] | F26: =SUM(H26,J26:O26) -> -721065 | H26: =FS.1!C13 -> 392 | I26: =I25 -> 500000 | J26: =FS.1!C14 -> 0 | K26: =FS.1!C17 -> 161256 | L26: 0 | M26: =-FS.1!C30 -> -603276 | N26: =-FS.1!C35 -> -5338 | O26: =-FS.1!C32-FS.1!C33 -> -274099 | P26: << current as of Dec 31 - QBO
C27: Change | D27: =SUM(H27:N27) -> -735276 | H27: =(H26-H25) -> -44055 | I27: =I26-I25 -> 0 | J27: =J26-J25 -> -49282 | K27: =K26-K25 -> -265878 | L27: =L26-L25 -> 0 | M27: =M26-M25 -> -371623 | N27: =N26-N25 -> -4438 | O27: =O26-O25 -> 13477
A29: Principal Purposes | B29: Funds ($)
A30: Total working capital available | B30: =B26 -> 90939
A31: Less: Estimated product commercialization | B31: =-50000 -> -50000
A32: Less: Advertising and marketing | B32: =-60000 -> -60000
A33: Less: Estimated test-trial expenses | B33: -18000
A34: Less: Estimated expenses related to the development of additional modular components | B34: =-20000 -> -20000
A35: Less: Estimated salaries | B35: =-372000 -> -372000
A36: Less: Estimated transaction fees (legal, accounting, listing fee, etc.) | B36: =-100000+55000-22000 -> -67000
A37: Total use of proceeds | B37: =SUM(B31:B36) -> -587000
A38: Unallocated funds (unaudited) | B38: =SUM(B30,B37) -> -496061 | C38: << must be positive $100k
A40: Minimum unallocated funds requirement | B40: =100000 -> 100000
A41: Cash short-fall to meet $100k requirment | B41: =IF((B38-B40)<0,B38-B40,0) -> -596061

Sheet Assumptions
A1: Assumptions | C1: input
C2: calculated
A4: 1) | B4: Estimate the # of sales agents to hire
B5: Avg # of units sold per agent each year | C5: 150
B6: Annual base salary | C6: 125000
B7: Commission % of gross profits per unit | C7: 0.1
B8: Gross profit per unit | C8: =#REF! -> #REF!
B9: Commission $ per unit | C9: =C7*C8 -> #REF!
B10: Potential total annual salary per agent | C10: =C6+(C5*C9) -> #REF!
B12: Ext- commission per unit sold | C12: 5000
C15: 2023 | D15: 2024 | E15: 2025 | F15: 2026 | H15: 45138 | I15: =EDATE(H15,12) -> 45504 | J15: =EDATE(I15,12) -> 45869 | K15: =EDATE(J15,12) -> 46234
C16: Year One | D16: Year Two | E16: Year Three | F16: Year Four | H16: Year One | I16: Year Two | J16: Year Three | K16: Year Four
B18: Projected unit sales | C18: =#REF! -> #REF! | D18: =#REF! -> #REF! | E18: =#REF! -> #REF! | F18: =#REF! -> #REF! | H18: =#REF! -> #REF! | I18: =SUM(#REF!,#REF!) -> #REF! | J18: =SUM(#REF!,#REF!) -> #REF! | K18: =SUM(#REF!,#REF!) -> #REF!
B19: # units allocated Gary | C19: =C18 -> #REF! | D19: 200 | E19: 200 | F19: 0 | H19: =H18 -> #REF! | I19: 200 | J19: 200 | K19: 0
B20: # units remaining | C20: =C18-C19 -> #REF! | D20: =D18-D19 -> #REF! | E20: =E18-E19 -> #REF! | F20: =F18-F19 -> #REF! | H20: =H18-H19 -> #REF! | I20: =I18-I19 -> #REF! | J20: =J18-J19 -> #REF! | K20: =K18-K19 -> #REF!
B21: # of sales agent needed | C21: =ROUND(C20/$C$5,0) -> #REF! | D21: =ROUND(D20/$C$5,0) -> #REF! | E21: =ROUND(E20/$C$5,0) -> #REF! | F21: =ROUND(F20/$C$5,0) -> #REF! | H21: =ROUND(H20/$C$5,0) -> #REF! | I21: =ROUND(I20/$C$5,0) -> #REF! | J21: =ROUND(J20/$C$5,0) -> #REF! | K21: =ROUND(K20/$C$5,0) -> #REF!
B23: Estimated Commissions | C23: =C19*$C$12 -> #REF! | D23: =D19*$C$12 -> 1000000 | E23: =E19*$C$12 -> 1000000 | F23: =F19*$C$12 -> 0 | H23: =H19*$C$12 -> #REF! | I23: =I19*$C$12 -> 1000000 | J23: =J19*$C$12 -> 1000000 | K23: =K19*$C$12 -> 0
B24: Estimated Payroll | C24: =C21*C10 -> #REF! | D24: =D21*$C$10 -> #REF! | E24: =E21*$C$10 -> #REF! | F24: =F21*$C$10 -> #REF! | H24: =H21*H10 -> #REF! | I24: =I21*$C$10 -> #REF! | J24: =J21*$C$10 -> #REF! | K24: =K21*$C$10 -> #REF!
B25: Total selling expense | C25: =SUM(C23:C24) -> #REF! | D25: =SUM(D23:D24) -> #REF! | E25: =SUM(E23:E24) -> #REF! | F25: =SUM(F23:F24) -> #REF! | H25: =SUM(H23:H24) -> #REF! | I25: =SUM(I23:I24) -> #REF! | J25: =SUM(J23:J24) -> #REF! | K25: =SUM(K23:K24) -> #REF!
C27: 2023 | D27: 2024 | E27: 2025 | F27: 2026 | H27: 2023 | I27: 2024 | J27: 2025 | K27: 2026
A28: 2 | B28: Payroll vs Commission structure | C28: Year One | D28: Year Two | E28: Year Three | F28: Year Four | H28: Year One | I28: Year Two | J28: Year Three | K28: Year Four
A30: a) | B30: Projected unit sales | C30: =C18 -> #REF! | D30: =D18 -> #REF! | E30: =E18 -> #REF! | F30: =F18 -> #REF! | H30: =H18 -> #REF! | I30: =I18 -> #REF! | J30: =J18 -> #REF! | K30: =K18 -> #REF!
B31: Commission per unit | C31: 5000 | D31: 5000 | E31: 5000 | F31: 5000 | H31: 5000 | I31: 5000 | J31: 5000 | K31: 5000
B32: Total Commission expense | C32: =C30*C31 -> #REF! | D32: =D30*D31 -> #REF! | E32: =E30*E31 -> #REF! | F32: =F30*F31 -> #REF! | H32: =H30*H31 -> #REF! | I32: =I30*I31 -> #REF! | J32: =J30*J31 -> #REF! | K32: =K30*K31 -> #REF!
A34: b) | B34: Projected unit sales | C34: =C18 -> #REF! | D34: =D18 -> #REF! | E34: =E18 -> #REF! | F34: =F18 -> #REF! | H34: =H18 -> #REF! | I34: =I18 -> #REF! | J34: =J18 -> #REF! | K34: =K18 -> #REF!
B35: # of sales agent needed | C35: =ROUNDUP(C34/$C$5,0) -> #REF! | D35: =ROUNDUP(D34/$C$5,0) -> #REF! | E35: =ROUNDUP(E34/$C$5,0) -> #REF! | F35: =ROUNDUP(F34/$C$5,0) -> #REF! | H35: =ROUNDUP(H34/$C$5,0) -> #REF! | I35: =ROUNDUP(I34/$C$5,0) -> #REF! | J35: =ROUNDUP(J34/$C$5,0) -> #REF! | K35: =ROUNDUP(K34/$C$5,0) -> #REF!
B36: Annual base salary | C36: =$C$6 -> 125000 | D36: =$C$6 -> 125000 | E36: =$C$6 -> 125000 | F36: =$C$6 -> 125000 | H36: =$C$6 -> 125000 | I36: =$C$6 -> 125000 | J36: =$C$6 -> 125000 | K36: =$C$6 -> 125000
B37: Commission $ per unit | C37: =$C$9 -> #REF! | D37: =$C$9 -> #REF! | E37: =$C$9 -> #REF! | F37: =$C$9 -> #REF! | H37: =$C$9 -> #REF! | I37: =$C$9 -> #REF! | J37: =$C$9 -> #REF! | K37: =$C$9 -> #REF!
B38: Total payroll expense (exluding benefits) | C38: =(C35*C36)+(C34*C37) -> #REF! | D38: =(D35*D36)+(D34*D37) -> #REF! | E38: =(E35*E36)+(E34*E37) -> #REF! | F38: =(F35*F36)+(F34*F37) -> #REF! | H38: =(H35*H36)+(H34*H37) -> #REF! | I38: =(I35*I36)+(I34*I37) -> #REF! | J38: =(J35*J36)+(J34*J37) -> #REF! | K38: =(K35*K36)+(K34*K37) -> #REF!
B40: Savings from hiring sales agent (a - b) | C40: =C32-C38 -> #REF! | D40: =D32-D38 -> #REF! | E40: =E32-E38 -> #REF! | F40: =F32-F38 -> #REF! | H40: =H32-H38 -> #REF! | I40: =I32-I38 -> #REF! | J40: =J32-J38 -> #REF! | K40: =K32-K38 -> #REF!

Sheet EXPORT >>
B2: This page intentionally blank

Sheet PROFORMA
A1: Balance Sheet | M1: Income Statement - Annual | O1: =O5/O3 -> 0.25206774 | Q1: =Q5/Q3 -> 0.25333328 | S1: =S5/S3 -> 0.25333333 | U1: =U5/U3 -> 0.25333334 | W1: =W5/W3 -> 0.25333333
A2: ="As at" -> As at | C2: =TEXT(FS.PRO!C8,"MMMM, DD, YYYY")&" (forecasted)" -> June, 30, 2026 (forecasted) | E2: =TEXT(FS.PRO!E8,"MMMM, DD, YYYY")&" (forecasted)" -> June, 30, 2027 (forecasted) | G2: =TEXT(FS.PRO!G8,"MMMM, DD, YYYY")&" (forecasted)" -> June, 30, 2028 (forecasted) | I2: =TEXT(FS.PRO!I8,"MMMM, DD, YYYY")&" (forecasted)" -> June, 30, 2029 (forecasted) | K2: =TEXT(FS.PRO!K8,"MMMM, DD, YYYY")&" (forecasted)" -> June, 30, 2030 (forecasted) | M2: For the years ended | O2: June, 30, 2026 (forecasted) | Q2: June, 30, 2027 (forecasted) | S2: June, 30, 2028 (forecasted) | U2: June, 30, 2029 (forecasted) | W2: June, 30, 2030 (forecasted) | AC2: Share Capital | AE2: Contributed Surplus | AG2: Accumulated Deficit | AI2: Total Shareholder's Equity
A3: ASSETS | M3: Sale of electric vehicle | N3: $ | O3: =_xlfn.XLOOKUP($M3,FS.PRO!$A:$A,FS.PRO!C:C,0,0,1) -> 507800 | P3: $ | Q3: =_xlfn.XLOOKUP($M3,FS.PRO!$A:$A,FS.PRO!E:E,0,0,1) -> 6531250 | R3: $ | S3: =_xlfn.XLOOKUP($M3,FS.PRO!$A:$A,FS.PRO!G:G,0,0,1) -> 29812500 | T3: $ | U3: =_xlfn.XLOOKUP($M3,FS.PRO!$A:$A,FS.PRO!I:I,0,0,1) -> 70812500 | V3: $ | W3: =_xlfn.XLOOKUP($M3,FS.PRO!$A:$A,FS.PRO!K:K,0,0,1) -> 124500000 | AA3: =FS.PRO!A102 -> Balance - June 30, 2025 | AB3: $ | AC3: =FS.PRO!C102 -> 8224099 | AD3: $ | AE3: =FS.PRO!E102 -> 308750 | AF3: $ | AG3: =FS.PRO!G102 -> -4977690 | AH3: $ | AI3: =ROUND(SUM(AC3:AG3),0) -> 3555159
A4: Current | M4: Cost of goods sold | N4: $ | O4: =_xlfn.XLOOKUP($M4,FS.PRO!$A:$A,FS.PRO!C:C,0,0,1) -> -379800 | P4: $ | Q4: =_xlfn.XLOOKUP($M4,FS.PRO!$A:$A,FS.PRO!E:E,0,0,1) -> -4876667 | R4: $ | S4: =_xlfn.XLOOKUP($M4,FS.PRO!$A:$A,FS.PRO!G:G,0,0,1) -> -22260000 | T4: $ | U4: =_xlfn.XLOOKUP($M4,FS.PRO!$A:$A,FS.PRO!I:I,0,0,1) -> -52873333 | V4: $ | W4: =_xlfn.XLOOKUP($M4,FS.PRO!$A:$A,FS.PRO!K:K,0,0,1) -> -92960000 | AA4: =FS.PRO!A103 -> Conversion of convertible debt to common shares | AC4: =FS.PRO!C103 -> 331121 | AE4: =FS.PRO!E103 -> 0 | AG4: =FS.PRO!G103 -> 0 | AI4: =ROUND(SUM(AC4:AG4),0) -> 331121
A5: =FS.1!A13 -> Cash | B5: $ | C5: =_xlfn.XLOOKUP($A5,FS.PRO!$A:$A,FS.PRO!C:C,0,0,1) -> 1942431 | D5: $ | E5: =_xlfn.XLOOKUP($A5,FS.PRO!$A:$A,FS.PRO!E:E,0,0,1) -> 1813362 | F5: $ | G5: =_xlfn.XLOOKUP($A5,FS.PRO!$A:$A,FS.PRO!G:G,0,0,1) -> 1408703 | H5: $ | I5: =_xlfn.XLOOKUP($A5,FS.PRO!$A:$A,FS.PRO!I:I,0,0,1) -> 9856641 | J5: $ | K5: =_xlfn.XLOOKUP($A5,FS.PRO!$A:$A,FS.PRO!K:K,0,0,1) -> 25432405 | M5: Gross profit (loss) | N5: $ | O5: =SUM(O3:O4) -> 128000 | P5: $ | Q5: =SUM(Q3:Q4) -> 1654583 | R5: $ | S5: =SUM(S3:S4) -> 7552500 | T5: $ | U5: =SUM(U3:U4) -> 17939167 | V5: $ | W5: =SUM(W3:W4) -> 31540000 | AA5: =FS.PRO!A104 -> Net loss for year | AC5: =FS.PRO!C104 -> 0 | AE5: =FS.PRO!E104 -> 0 | AG5: =FS.PRO!G104 -> -1831200 | AI5: =ROUND(SUM(AC5:AG5),0) -> -1831200
A6: =FS.PRO!A14 -> Receivables | C6: =_xlfn.XLOOKUP($A6,FS.PRO!$A:$A,FS.PRO!C:C,0,0,1) -> 18 | E6: =_xlfn.XLOOKUP($A6,FS.PRO!$A:$A,FS.PRO!E:E,0,0,1) -> 18 | G6: =_xlfn.XLOOKUP($A6,FS.PRO!$A:$A,FS.PRO!G:G,0,0,1) -> 18 | I6: =_xlfn.XLOOKUP($A6,FS.PRO!$A:$A,FS.PRO!I:I,0,0,1) -> 18 | K6: =_xlfn.XLOOKUP($A6,FS.PRO!$A:$A,FS.PRO!K:K,0,0,1) -> 18 | M6: Operating expenses | AA6: =FS.PRO!A105 -> Balance - June 30, 2026 | AB6: $ | AC6: =ROUND(SUM(AC3:AC5),0) -> 8555220 | AD6: $ | AE6: =ROUND(SUM(AE3:AE5),0) -> 308750 | AF6: $ | AG6: =ROUND(SUM(AG3:AG5),0) -> -6808890 | AH6: $ | AI6: =ROUND(SUM(AI3:AI5),0) -> 2055080
A7: =FS.PRO!A17 -> Inventory | C7: =_xlfn.XLOOKUP($A7,FS.PRO!$A:$A,FS.PRO!C:C,0,0,1) -> 159517 | E7: =_xlfn.XLOOKUP($A7,FS.PRO!$A:$A,FS.PRO!E:E,0,0,1) -> 602850 | G7: =_xlfn.XLOOKUP($A7,FS.PRO!$A:$A,FS.PRO!G:G,0,0,1) -> 2142850 | I7: =_xlfn.XLOOKUP($A7,FS.PRO!$A:$A,FS.PRO!I:I,0,0,1) -> 5269517 | K7: =_xlfn.XLOOKUP($A7,FS.PRO!$A:$A,FS.PRO!K:K,0,0,1) -> 10309517 | M7: =FS.PRO!A60 -> Bank fees | N7: $ | O7: =_xlfn.XLOOKUP($M7,FS.PRO!$A:$A,FS.PRO!C:C,0,0,1) -> 2074 | P7: $ | Q7: =_xlfn.XLOOKUP($M7,FS.PRO!$A:$A,FS.PRO!E:E,0,0,1) -> 2514 | R7: $ | S7: =_xlfn.XLOOKUP($M7,FS.PRO!$A:$A,FS.PRO!G:G,0,0,1) -> 2639 | T7: $ | U7: =_xlfn.XLOOKUP($M7,FS.PRO!$A:$A,FS.PRO!I:I,0,0,1) -> 2772 | V7: $ | W7: =_xlfn.XLOOKUP($M7,FS.PRO!$A:$A,FS.PRO!K:K,0,0,1) -> 2910 | AA7: Net loss for year | AC7: =FS.PRO!C106 -> 0 | AE7: =FS.PRO!E106 -> 0 | AG7: =FS.PRO!G106 -> -1647899 | AI7: =ROUND(SUM(AC7:AG7),0) -> -1647899
A8: =FS.1!A20 -> Total current assets | B8: $ | C8: =SUM(C5:C7) -> 2101966 | D8: $ | E8: =SUM(E5:E7) -> 2416230 | F8: $ | G8: =SUM(G5:G7) -> 3551571 | H8: $ | I8: =SUM(I5:I7) -> 15126176 | J8: $ | K8: =SUM(K5:K7) -> 35741940 | M8: =FS.PRO!A61 -> Professional fees | O8: =_xlfn.XLOOKUP($M8,FS.PRO!$A:$A,FS.PRO!C:C,0,0,1) -> 111500 | Q8: =_xlfn.XLOOKUP($M8,FS.PRO!$A:$A,FS.PRO!E:E,0,0,1) -> 90000 | S8: =_xlfn.XLOOKUP($M8,FS.PRO!$A:$A,FS.PRO!G:G,0,0,1) -> 90000 | U8: =_xlfn.XLOOKUP($M8,FS.PRO!$A:$A,FS.PRO!I:I,0,0,1) -> 108000 | W8: =_xlfn.XLOOKUP($M8,FS.PRO!$A:$A,FS.PRO!K:K,0,0,1) -> 129600 | AA8: =FS.PRO!A107 -> Balance - June 30, 2027 | AB8: $ | AC8: =SUM(AC6:AC7) -> 8555220 | AD8: $ | AE8: =SUM(AE6:AE7) -> 308750 | AF8: $ | AG8: =SUM(AG6:AG7) -> -8456789 | AH8: $ | AI8: =SUM(AI6:AI7) -> 407181
A9: =FS.1!A21 -> Non-current assets | M9: =FS.PRO!A62 -> Consulting expense | O9: =_xlfn.XLOOKUP($M9,FS.PRO!$A:$A,FS.PRO!C:C,0,0,1) -> 273417 | Q9: =_xlfn.XLOOKUP($M9,FS.PRO!$A:$A,FS.PRO!E:E,0,0,1) -> 276000 | S9: =_xlfn.XLOOKUP($M9,FS.PRO!$A:$A,FS.PRO!G:G,0,0,1) -> 276000 | U9: =_xlfn.XLOOKUP($M9,FS.PRO!$A:$A,FS.PRO!I:I,0,0,1) -> 276000 | W9: =_xlfn.XLOOKUP($M9,FS.PRO!$A:$A,FS.PRO!K:K,0,0,1) -> 276000 | AA9: Net loss for year | AC9: =FS.PRO!C108 -> 0 | AE9: =FS.PRO!E108 -> 0 | AG9: =FS.PRO!G108 -> 336928 | AI9: =ROUND(SUM(AC9:AG9),0) -> 336928
A10: =FS.PRO!A23 -> Equipment | C10: =_xlfn.XLOOKUP($A10,FS.PRO!$A:$A,FS.PRO!C:C,0,0,1) -> 3442 | E10: =_xlfn.XLOOKUP($A10,FS.PRO!$A:$A,FS.PRO!E:E,0,0,1) -> 3442 | G10: =_xlfn.XLOOKUP($A10,FS.PRO!$A:$A,FS.PRO!G:G,0,0,1) -> 3442 | I10: =_xlfn.XLOOKUP($A10,FS.PRO!$A:$A,FS.PRO!I:I,0,0,1) -> 3442 | K10: =_xlfn.XLOOKUP($A10,FS.PRO!$A:$A,FS.PRO!K:K,0,0,1) -> 3442 | M10: =FS.PRO!A63 -> Dues, licenses, and permits | O10: =_xlfn.XLOOKUP($M10,FS.PRO!$A:$A,FS.PRO!C:C,0,0,1) -> 2194 | Q10: =_xlfn.XLOOKUP($M10,FS.PRO!$A:$A,FS.PRO!E:E,0,0,1) -> 1812 | S10: =_xlfn.XLOOKUP($M10,FS.PRO!$A:$A,FS.PRO!G:G,0,0,1) -> 1849 | U10: =_xlfn.XLOOKUP($M10,FS.PRO!$A:$A,FS.PRO!I:I,0,0,1) -> 1886 | W10: =_xlfn.XLOOKUP($M10,FS.PRO!$A:$A,FS.PRO!K:K,0,0,1) -> 1923 | AA10: =FS.PRO!A109 -> Balance - June 30, 2028 | AB10: $ | AC10: =SUM(AC8:AC9) -> 8555220 | AD10: $ | AE10: =SUM(AE8:AE9) -> 308750 | AF10: $ | AG10: =SUM(AG8:AG9) -> -8119861 | AH10: $ | AI10: =SUM(AI8:AI9) -> 744109
A11: =FS.PRO!A24 -> Intangible assets | C11: =_xlfn.XLOOKUP($A11,FS.PRO!$A:$A,FS.PRO!C:C,0,0,1) -> 3015078 | E11: =_xlfn.XLOOKUP($A11,FS.PRO!$A:$A,FS.PRO!E:E,0,0,1) -> 1758714 | G11: =_xlfn.XLOOKUP($A11,FS.PRO!$A:$A,FS.PRO!G:G,0,0,1) -> 502350 | I11: =_xlfn.XLOOKUP($A11,FS.PRO!$A:$A,FS.PRO!I:I,0,0,1) -> 314091 | K11: =_xlfn.XLOOKUP($A11,FS.PRO!$A:$A,FS.PRO!K:K,0,0,1) -> 314091 | M11: =FS.PRO!A64 -> Advertising and marketing | O11: =_xlfn.XLOOKUP($M11,FS.PRO!$A:$A,FS.PRO!C:C,0,0,1) -> 78640 | Q11: =_xlfn.XLOOKUP($M11,FS.PRO!$A:$A,FS.PRO!E:E,0,0,1) -> 434250 | S11: =_xlfn.XLOOKUP($M11,FS.PRO!$A:$A,FS.PRO!G:G,0,0,1) -> 1671750 | U11: =_xlfn.XLOOKUP($M11,FS.PRO!$A:$A,FS.PRO!I:I,0,0,1) -> 3828000 | W11: =_xlfn.XLOOKUP($M11,FS.PRO!$A:$A,FS.PRO!K:K,0,0,1) -> 6640500 | AA11: Net income for year | AC11: =FS.PRO!C110 -> 0 | AE11: =FS.PRO!E110 -> 0 | AG11: =FS.PRO!G110 -> 5998846 | AI11: =ROUND(SUM(AC11:AG11),0) -> 5998846
A12: =FS.1!A26 -> Total non-current assets | B12: $ | C12: =SUM(C10:C11) -> 3018520 | D12: $ | E12: =SUM(E10:E11) -> 1762156 | F12: $ | G12: =SUM(G10:G11) -> 505792 | H12: $ | I12: =SUM(I10:I11) -> 317533 | J12: $ | K12: =SUM(K10:K11) -> 317533 | M12: =FS.PRO!A65 -> Meals and entertainment | O12: =_xlfn.XLOOKUP($M12,FS.PRO!$A:$A,FS.PRO!C:C,0,0,1) -> 3000 | Q12: =_xlfn.XLOOKUP($M12,FS.PRO!$A:$A,FS.PRO!E:E,0,0,1) -> 3300 | S12: =_xlfn.XLOOKUP($M12,FS.PRO!$A:$A,FS.PRO!G:G,0,0,1) -> 3630 | U12: =_xlfn.XLOOKUP($M12,FS.PRO!$A:$A,FS.PRO!I:I,0,0,1) -> 3993 | W12: =_xlfn.XLOOKUP($M12,FS.PRO!$A:$A,FS.PRO!K:K,0,0,1) -> 4392 | AA12: =FS.PRO!A111 -> Balance - June 30, 2029 | AB12: $ | AC12: =SUM(AC10:AC11) -> 8555220 | AD12: $ | AE12: =SUM(AE10:AE11) -> 308750 | AF12: $ | AG12: =SUM(AG10:AG11) -> -2121015 | AH12: $ | AI12: =SUM(AI10:AI11) -> 6742955
A13: =FS.1!A27 -> Total Assets | B13: $ | C13: =C12+C8 -> 5120486 | D13: $ | E13: =E12+E8 -> 4178386 | F13: $ | G13: =G12+G8 -> 4057363 | H13: $ | I13: =I12+I8 -> 15443709 | J13: $ | K13: =K12+K8 -> 36059473 | M13: =FS.PRO!A66 -> Travel expenses | O13: =_xlfn.XLOOKUP($M13,FS.PRO!$A:$A,FS.PRO!C:C,0,0,1) -> 6000 | Q13: =_xlfn.XLOOKUP($M13,FS.PRO!$A:$A,FS.PRO!E:E,0,0,1) -> 6600 | S13: =_xlfn.XLOOKUP($M13,FS.PRO!$A:$A,FS.PRO!G:G,0,0,1) -> 7260 | U13: =_xlfn.XLOOKUP($M13,FS.PRO!$A:$A,FS.PRO!I:I,0,0,1) -> 7986 | W13: =_xlfn.XLOOKUP($M13,FS.PRO!$A:$A,FS.PRO!K:K,0,0,1) -> 8785 | AA13: Net income for year | AC13: =FS.PRO!C112 -> 0 | AE13: =FS.PRO!E112 -> 0 | AG13: =FS.PRO!G112 -> 11765764 | AI13: =ROUND(SUM(AC13:AG13),0) -> 11765764
A14: LIABILITIES | M14: =FS.PRO!A67 -> Transfer agent and regulatory expenses | O14: =_xlfn.XLOOKUP($M14,FS.PRO!$A:$A,FS.PRO!C:C,0,0,1) -> 9000 | Q14: =_xlfn.XLOOKUP($M14,FS.PRO!$A:$A,FS.PRO!E:E,0,0,1) -> 9450 | S14: =_xlfn.XLOOKUP($M14,FS.PRO!$A:$A,FS.PRO!G:G,0,0,1) -> 9923 | U14: =_xlfn.XLOOKUP($M14,FS.PRO!$A:$A,FS.PRO!I:I,0,0,1) -> 10419 | W14: =_xlfn.XLOOKUP($M14,FS.PRO!$A:$A,FS.PRO!K:K,0,0,1) -> 10940 | AA14: =FS.PRO!A113 -> Balance - June 30, 2030 | AB14: $ | AC14: =SUM(AC12:AC13) -> 8555220 | AD14: $ | AE14: =SUM(AE12:AE13) -> 308750 | AF14: $ | AG14: =SUM(AG12:AG13) -> 9644749 | AH14: $ | AI14: =SUM(AI12:AI13) -> 18508719
A15: Current liabilities | M15: =FS.PRO!A68 -> Insurance | O15: =_xlfn.XLOOKUP($M15,FS.PRO!$A:$A,FS.PRO!C:C,0,0,1) -> 30204 | Q15: =_xlfn.XLOOKUP($M15,FS.PRO!$A:$A,FS.PRO!E:E,0,0,1) -> 31500 | S15: =_xlfn.XLOOKUP($M15,FS.PRO!$A:$A,FS.PRO!G:G,0,0,1) -> 33075 | U15: =_xlfn.XLOOKUP($M15,FS.PRO!$A:$A,FS.PRO!I:I,0,0,1) -> 34729 | W15: =_xlfn.XLOOKUP($M15,FS.PRO!$A:$A,FS.PRO!K:K,0,0,1) -> 36465
A16: =FS.PRO!A31 -> Accrued Warranty Liability | C16: =_xlfn.XLOOKUP($A16,FS.PRO!$A:$A,FS.PRO!C:C,0,0,1) -> 64506 | E16: =_xlfn.XLOOKUP($A16,FS.PRO!$A:$A,FS.PRO!E:E,0,0,1) -> 176555 | G16: =_xlfn.XLOOKUP($A16,FS.PRO!$A:$A,FS.PRO!G:G,0,0,1) -> 656104 | I16: =_xlfn.XLOOKUP($A16,FS.PRO!$A:$A,FS.PRO!I:I,0,0,1) -> 1856104 | K16: =_xlfn.XLOOKUP($A16,FS.PRO!$A:$A,FS.PRO!K:K,0,0,1) -> 3956104 | M16: =FS.PRO!A69 -> Office expenses | O16: =_xlfn.XLOOKUP($M16,FS.PRO!$A:$A,FS.PRO!C:C,0,0,1) -> 24589 | Q16: =_xlfn.XLOOKUP($M16,FS.PRO!$A:$A,FS.PRO!E:E,0,0,1) -> 26400 | S16: =_xlfn.XLOOKUP($M16,FS.PRO!$A:$A,FS.PRO!G:G,0,0,1) -> 29040 | U16: =_xlfn.XLOOKUP($M16,FS.PRO!$A:$A,FS.PRO!I:I,0,0,1) -> 31944 | W16: =_xlfn.XLOOKUP($M16,FS.PRO!$A:$A,FS.PRO!K:K,0,0,1) -> 35138 | AA16: CHECK | AC16: =FS.PRO!C105-AC6 -> 0 | AE16: =FS.PRO!E105-AE6 -> 0 | AG16: =FS.PRO!G105-AG6 -> 0 | AI16: =FS.PRO!I105-AI6 -> 0
A17: =FS.PRO!A33 -> Deferred revenue | C17: =_xlfn.XLOOKUP($A17,FS.PRO!$A:$A,FS.PRO!C:C,0,0,1) -> 0 | E17: =_xlfn.XLOOKUP($A17,FS.PRO!$A:$A,FS.PRO!E:E,0,0,1) -> 593750 | G17: =_xlfn.XLOOKUP($A17,FS.PRO!$A:$A,FS.PRO!G:G,0,0,1) -> 2656250 | I17: =_xlfn.XLOOKUP($A17,FS.PRO!$A:$A,FS.PRO!I:I,0,0,1) -> 6843750 | K17: =_xlfn.XLOOKUP($A17,FS.PRO!$A:$A,FS.PRO!K:K,0,0,1) -> 13593750 | M17: =FS.PRO!A70 -> Selling expense | O17: =_xlfn.XLOOKUP($M17,FS.PRO!$A:$A,FS.PRO!C:C,0,0,1) -> 0 | Q17: =_xlfn.XLOOKUP($M17,FS.PRO!$A:$A,FS.PRO!E:E,0,0,1) -> 60000 | S17: =_xlfn.XLOOKUP($M17,FS.PRO!$A:$A,FS.PRO!G:G,0,0,1) -> 1275000 | U17: =_xlfn.XLOOKUP($M17,FS.PRO!$A:$A,FS.PRO!I:I,0,0,1) -> 3000000 | W17: =_xlfn.XLOOKUP($M17,FS.PRO!$A:$A,FS.PRO!K:K,0,0,1) -> 5250000 | AA17: CHECK | AC17: =FS.PRO!C107-AC8 -> 0 | AE17: =FS.PRO!E107-AE8 -> 0 | AG17: =FS.PRO!G107-AG8 -> 0 | AI17: =FS.PRO!I107-AI8 -> 0
A18: =FS.PRO!A34 -> Due to related parties | C18: =_xlfn.XLOOKUP($A18,FS.PRO!$A:$A,FS.PRO!C:C,0,0,1) -> 900 | E18: =_xlfn.XLOOKUP($A18,FS.PRO!$A:$A,FS.PRO!E:E,0,0,1) -> 900 | G18: =_xlfn.XLOOKUP($A18,FS.PRO!$A:$A,FS.PRO!G:G,0,0,1) -> 900 | I18: =_xlfn.XLOOKUP($A18,FS.PRO!$A:$A,FS.PRO!I:I,0,0,1) -> 900 | K18: =_xlfn.XLOOKUP($A18,FS.PRO!$A:$A,FS.PRO!K:K,0,0,1) -> 900 | M18: =FS.PRO!A71 -> Shipping expense | O18: =_xlfn.XLOOKUP($M18,FS.PRO!$A:$A,FS.PRO!C:C,0,0,1) -> 6000 | Q18: =_xlfn.XLOOKUP($M18,FS.PRO!$A:$A,FS.PRO!E:E,0,0,1) -> 142500 | S18: =_xlfn.XLOOKUP($M18,FS.PRO!$A:$A,FS.PRO!G:G,0,0,1) -> 637500 | U18: =_xlfn.XLOOKUP($M18,FS.PRO!$A:$A,FS.PRO!I:I,0,0,1) -> 1500000 | W18: =_xlfn.XLOOKUP($M18,FS.PRO!$A:$A,FS.PRO!K:K,0,0,1) -> 2625000 | AA18: CHECK | AC18: =FS.PRO!C109-AC10 -> 0 | AE18: =FS.PRO!E109-AE10 -> 0 | AG18: =FS.PRO!G109-AG10 -> 0 | AI18: =FS.PRO!I109-AI10 -> 0
A19: =FS.1!A37 -> Non-current liabilities | B19: $ | C19: =SUM(C16:C18) -> 65406 | D19: $ | E19: =SUM(E16:E18) -> 771205 | F19: $ | G19: =SUM(G16:G18) -> 3313254 | H19: $ | I19: =SUM(I16:I18) -> 8700754 | J19: $ | K19: =SUM(K16:K18) -> 17550754 | M19: =FS.PRO!A72 -> Shop supplies | O19: =_xlfn.XLOOKUP($M19,FS.PRO!$A:$A,FS.PRO!C:C,0,0,1) -> 3633 | Q19: =_xlfn.XLOOKUP($M19,FS.PRO!$A:$A,FS.PRO!E:E,0,0,1) -> 86292 | S19: =_xlfn.XLOOKUP($M19,FS.PRO!$A:$A,FS.PRO!G:G,0,0,1) -> 386042 | U19: =_xlfn.XLOOKUP($M19,FS.PRO!$A:$A,FS.PRO!I:I,0,0,1) -> 908333 | W19: =_xlfn.XLOOKUP($M19,FS.PRO!$A:$A,FS.PRO!K:K,0,0,1) -> 1589583 | AA19: CHECK | AC19: =FS.PRO!C111-AC12 -> 0 | AE19: =FS.PRO!E111-AE12 -> 0 | AG19: =FS.PRO!G111-AG12 -> 0 | AI19: =FS.PRO!I111-AI12 -> 0
A20: =FS.PRO!A39 -> Loans and borrowings | C20: =_xlfn.XLOOKUP($A20,FS.PRO!$A:$A,FS.PRO!C:C,0,0,1) -> 3000000 | E20: =_xlfn.XLOOKUP($A20,FS.PRO!$A:$A,FS.PRO!E:E,0,0,1) -> 3000000 | G20: =_xlfn.XLOOKUP($A20,FS.PRO!$A:$A,FS.PRO!G:G,0,0,1) -> 0 | I20: =_xlfn.XLOOKUP($A20,FS.PRO!$A:$A,FS.PRO!I:I,0,0,1) -> 0 | K20: =_xlfn.XLOOKUP($A20,FS.PRO!$A:$A,FS.PRO!K:K,0,0,1) -> 0 | M20: =FS.PRO!A73 -> Warranty expense | O20: =_xlfn.XLOOKUP($M20,FS.PRO!$A:$A,FS.PRO!C:C,0,0,1) -> 9756 | Q20: =_xlfn.XLOOKUP($M20,FS.PRO!$A:$A,FS.PRO!E:E,0,0,1) -> 142500 | S20: =_xlfn.XLOOKUP($M20,FS.PRO!$A:$A,FS.PRO!G:G,0,0,1) -> 637500 | U20: =_xlfn.XLOOKUP($M20,FS.PRO!$A:$A,FS.PRO!I:I,0,0,1) -> 1500000 | W20: =_xlfn.XLOOKUP($M20,FS.PRO!$A:$A,FS.PRO!K:K,0,0,1) -> 2625000 | AA20: CHECK | AC20: =FS.PRO!C113-AC14 -> 0 | AE20: =FS.PRO!E113-AE14 -> 0 | AG20: =FS.PRO!G113-AG14 -> 0 | AI20: =FS.PRO!I113-AI14 -> 0
A21: =FS.1!A39 -> Total Liabilities | C21: =SUM(C19:C20) -> 3065406 | E21: =SUM(E19:E20) -> 3771205 | G21: =SUM(G19:G20) -> 3313254 | I21: =SUM(I19:I20) -> 8700754 | K21: =SUM(K19:K20) -> 17550754 | M21: =FS.PRO!A74 -> Amortization expense | O21: =_xlfn.XLOOKUP($M21,FS.PRO!$A:$A,FS.PRO!C:C,0,0,1) -> 1256364 | Q21: =_xlfn.XLOOKUP($M21,FS.PRO!$A:$A,FS.PRO!E:E,0,0,1) -> 1256364 | S21: =_xlfn.XLOOKUP($M21,FS.PRO!$A:$A,FS.PRO!G:G,0,0,1) -> 1256364 | U21: =_xlfn.XLOOKUP($M21,FS.PRO!$A:$A,FS.PRO!I:I,0,0,1) -> 188259 | W21: =_xlfn.XLOOKUP($M21,FS.PRO!$A:$A,FS.PRO!K:K,0,0,1) -> 0
A22: SHAREHOLDERS’ EQUITY | M22: =FS.PRO!A75 -> Foreign exchange | O22: =_xlfn.XLOOKUP($M22,FS.PRO!$A:$A,FS.PRO!C:C,0,0,1) -> -69 | Q22: =_xlfn.XLOOKUP($M22,FS.PRO!$A:$A,FS.PRO!E:E,0,0,1) -> 0 | S22: =_xlfn.XLOOKUP($M22,FS.PRO!$A:$A,FS.PRO!G:G,0,0,1) -> 0 | U22: =_xlfn.XLOOKUP($M22,FS.PRO!$A:$A,FS.PRO!I:I,0,0,1) -> 0 | W22: =_xlfn.XLOOKUP($M22,FS.PRO!$A:$A,FS.PRO!K:K,0,0,1) -> 0
A23: =FS.1!A41 -> Share capital | B23: $ | C23: =_xlfn.XLOOKUP($A23,FS.PRO!$A:$A,FS.PRO!C:C,0,0,1) -> 8555220 | D23: $ | E23: =_xlfn.XLOOKUP($A23,FS.PRO!$A:$A,FS.PRO!E:E,0,0,1) -> 8555220 | F23: $ | G23: =_xlfn.XLOOKUP($A23,FS.PRO!$A:$A,FS.PRO!G:G,0,0,1) -> 8555220 | H23: $ | I23: =_xlfn.XLOOKUP($A23,FS.PRO!$A:$A,FS.PRO!I:I,0,0,1) -> 8555220 | J23: $ | K23: =_xlfn.XLOOKUP($A23,FS.PRO!$A:$A,FS.PRO!K:K,0,0,1) -> 8555220 | M23: =FS.PRO!A76 -> Rent | O23: =_xlfn.XLOOKUP($M23,FS.PRO!$A:$A,FS.PRO!C:C,0,0,1) -> 12000 | Q23: =_xlfn.XLOOKUP($M23,FS.PRO!$A:$A,FS.PRO!E:E,0,0,1) -> 63000 | S23: =_xlfn.XLOOKUP($M23,FS.PRO!$A:$A,FS.PRO!G:G,0,0,1) -> 228000 | U23: =_xlfn.XLOOKUP($M23,FS.PRO!$A:$A,FS.PRO!I:I,0,0,1) -> 228000 | W23: =_xlfn.XLOOKUP($M23,FS.PRO!$A:$A,FS.PRO!K:K,0,0,1) -> 228000
A24: =FS.1!A42 -> Contributed surplus | C24: =_xlfn.XLOOKUP($A24,FS.PRO!$A:$A,FS.PRO!C:C,0,0,1) -> 308750 | E24: =_xlfn.XLOOKUP($A24,FS.PRO!$A:$A,FS.PRO!E:E,0,0,1) -> 308750 | G24: =_xlfn.XLOOKUP($A24,FS.PRO!$A:$A,FS.PRO!G:G,0,0,1) -> 308750 | I24: =_xlfn.XLOOKUP($A24,FS.PRO!$A:$A,FS.PRO!I:I,0,0,1) -> 308750 | K24: =_xlfn.XLOOKUP($A24,FS.PRO!$A:$A,FS.PRO!K:K,0,0,1) -> 308750 | M24: =FS.PRO!A77 -> Research and development | O24: =_xlfn.XLOOKUP($M24,FS.PRO!$A:$A,FS.PRO!C:C,0,0,1) -> 0 | Q24: =_xlfn.XLOOKUP($M24,FS.PRO!$A:$A,FS.PRO!E:E,0,0,1) -> 310000 | S24: =_xlfn.XLOOKUP($M24,FS.PRO!$A:$A,FS.PRO!G:G,0,0,1) -> 310000 | U24: =_xlfn.XLOOKUP($M24,FS.PRO!$A:$A,FS.PRO!I:I,0,0,1) -> 310000 | W24: =_xlfn.XLOOKUP($M24,FS.PRO!$A:$A,FS.PRO!K:K,0,0,1) -> 310000
A25: =FS.1!A43 -> Accumulated deficit | C25: =_xlfn.XLOOKUP($A25,FS.PRO!$A:$A,FS.PRO!C:C,0,0,1) -> -6808890 | E25: =_xlfn.XLOOKUP($A25,FS.PRO!$A:$A,FS.PRO!E:E,0,0,1) -> -8456789 | G25: =_xlfn.XLOOKUP($A25,FS.PRO!$A:$A,FS.PRO!G:G,0,0,1) -> -8119861 | I25: =_xlfn.XLOOKUP($A25,FS.PRO!$A:$A,FS.PRO!I:I,0,0,1) -> -2121015 | K25: =_xlfn.XLOOKUP($A25,FS.PRO!$A:$A,FS.PRO!K:K,0,0,1) -> 9644749 | M25: Total operating expenses | N25: $ | O25: =-SUM(O7:O24) -> -1828302 | P25: $ | Q25: =-SUM(Q7:Q24) -> -2942482 | R25: $ | S25: =-SUM(S7:S24) -> -6855572 | T25: $ | U25: =-SUM(U7:U24) -> -11940321 | V25: $ | W25: =-SUM(W7:W24) -> -19774236
A26: TOTAL SHAREHOLDERS’ EQUITY | B26: $ | C26: =SUM(C23:C25) -> 2055080 | D26: $ | E26: =SUM(E23:E25) -> 407181 | F26: $ | G26: =SUM(G23:G25) -> 744109 | H26: $ | I26: =SUM(I23:I25) -> 6742955 | J26: $ | K26: =SUM(K23:K25) -> 18508719 | M26: Net operating income / (loss) | N26: $ | O26: =SUM(O5,O25) -> -1700302 | P26: $ | Q26: =SUM(Q5,Q25) -> -1287899 | R26: $ | S26: =SUM(S5,S25) -> 696928 | T26: $ | U26: =SUM(U5,U25) -> 5998846 | V26: $ | W26: =SUM(W5,W25) -> 11765764
A27: TOTAL LIABILITIES AND SHAREHOLDERS’ EQUITY | B27: $ | C27: =C26+C21 -> 5120486 | D27: $ | E27: =E26+E21 -> 4178386 | F27: $ | G27: =G26+G21 -> 4057363 | H27: $ | I27: =I26+I21 -> 15443709 | J27: $ | K27: =K26+K21 -> 36059473 | M27: =FS.PRO!A81 -> Other income (expenses)
M28: Other income | O28: =_xlfn.XLOOKUP($M28,FS.PRO!$A:$A,FS.PRO!C:C,0,0,1) -> 47085 | Q28: =_xlfn.XLOOKUP($M28,FS.PRO!$A:$A,FS.PRO!E:E,0,0,1) -> 0 | S28: =_xlfn.XLOOKUP($M28,FS.PRO!$A:$A,FS.PRO!G:G,0,0,1) -> 0 | U28: =_xlfn.XLOOKUP($M28,FS.PRO!$A:$A,FS.PRO!I:I,0,0,1) -> 0 | W28: =_xlfn.XLOOKUP($M28,FS.PRO!$A:$A,FS.PRO!K:K,0,0,1) -> 0
A29: CHECK | C29: =FS.PRO!C47-C27 -> 0 | E29: =FS.PRO!E47-E27 -> 0 | G29: =FS.PRO!G47-G27 -> 0 | I29: =FS.PRO!I47-I27 -> 0 | K29: =FS.PRO!K47-K27 -> 0 | M29: =FS.PRO!A84 -> Net financial expenses | O29: =_xlfn.XLOOKUP($M29,FS.PRO!$A:$A,FS.PRO!C:C,0,0,1) -> -36210 | Q29: =_xlfn.XLOOKUP($M29,FS.PRO!$A:$A,FS.PRO!E:E,0,0,1) -> 0 | S29: =_xlfn.XLOOKUP($M29,FS.PRO!$A:$A,FS.PRO!G:G,0,0,1) -> 0 | U29: =_xlfn.XLOOKUP($M29,FS.PRO!$A:$A,FS.PRO!I:I,0,0,1) -> 0 | W29: =_xlfn.XLOOKUP($M29,FS.PRO!$A:$A,FS.PRO!K:K,0,0,1) -> 0
